Workbook

Sheet Read Me
A1: Read Me — Tab Guide & Legend
A2: Connect QA Gap Analysis · Web Platform stream
A4: TWO OUTPUTS OF THIS EXERCISE
A5: Output 1: MTP completeness | B5: Everything the product does that was NOT documented in this test plan. ALL functional gaps get added to the plan, whether or not engineering already tests them.
A6: Output 2: QA automation backlog | B6: The subset QA still needs to automate — the ones engineering does NOT already cover. Filter the Gap Analysis Action column for "Automate".
A8: TAB GUIDE (4 analysis tabs)
A9: Read Me | B9: This tab. The key to the workbook.
A10: Dashboard | B10: One-screen live dashboard: the two outputs (add-to-MTP / automate), dev + reconcile counts, AND the Coverage Tracker — per-surface automation % of existing MTP cases. Read this first.
A11: Gap Analysis (MAIN OUTPUT) | B11: Every coverage gap found — behaviour in the code with NO case in the test plan. Each row has its Bucket, Eng Coverage, and Action. Reviewers work here.
A12: Automation (existing MTP) | B12: The existing master test cases and their automation status: Green = already automated, Yellow = automatable-not-built, Red = manual-only. (This is the pass-1 baseline; the Dashboard Coverage Tracker rolls it up.)
A14: ORIGINAL TABS (not from this exercise)
A15: Test Tracker / Test Tracker Horizontal | B15: Pre-existing manual-execution trackers (run pass/fail). Left untouched.
A16: Surface tabs (Login, Opportunity creation, Visit verification, ...) | B16: The existing master test plan — documented cases by product area. The "before" picture the gap analysis was measured against.
A18: GAP ANALYSIS — 3 row types (by Gap ID prefix)
A19: Functional gap | B19: Behaviour in code with no MTP case. Core finding. IDs: GAP-SRC-*, GAP-BE-*, GAP-FE-*.
A20: Unit-test-coverage gap (dev) | B20: Where ENG code lacks a unit test. For dev teams. IDs: GAP-UTC-*.
A21: Cross-cutting | B21: Hygiene / MTP-vs-code discrepancy / automation note. IDs: GAP-MISC-*, GAP-MMISC-*.
A23: BUCKET column | B23: 🟢 Already automated · 🟡 Automatable-not-done (backlog) · 🔴 Manual only (real SMS/OTP/push/camera/device)
A24: ENG COVERAGE column | B24: Eng-covered (logic) = eng already tests it, QA e2e only if critical · QA-owned = eng cannot cover · Partial = confirm w/ eng · Eng GAP = eng missing a unit test · N/A
A25: ACTION column | B25: Add to MTP only (eng-covered) · Add to MTP + Automate (QA-owned) · Add to MTP + Automate (confirm w/ eng) · Dev: add unit test · Reconcile (plan/code)

Sheet Dashboard
A1: Dashboard — conclusions, outputs & coverage (live)
A3: CONCLUSIONS / ANALYSIS NOTES
A4: • Method: audited the master test plans against the actual product code to find behaviour with no test case (functional gaps), then cross-referenced each against engineering PR-run tests so QA does not duplicate eng work.
A5: • Two outputs: (1) MTP completeness = ALL functional gaps get added to the plan; (2) QA automation backlog = only the gaps eng does NOT already cover.
A6: • New gaps are mostly eng-covered: the majority of functional gaps found in code are already tested by eng at the logic layer -> add to MTP for completeness, but do NOT re-automate. QA new-automation shortlist is small (real device/SMS/push/cross-system).
A7: • Existing MTP backlog is the opposite: automatable-not-built existing cases are overwhelmingly UI / end-to-end journeys that eng unit tests do NOT cover -> this backlog genuinely needs QA automation (not duplicative of eng).
A8: • Net: eng-overlap savings land almost entirely on the NEW gaps, not the existing backlog. Manual-only (red) items stay manual regardless of framework.
A9: • All eng-coverage tags are best-guess from reading eng test structure, not verified line coverage - confirm the Partial items with the dev teams.
A11: OUTPUTS (from Gap Analysis)
A12: Output 1: functional gaps to ADD to MTP | B12: =COUNTIF('Gap Analysis'!$L:$L,"Add to MTP*")
A13: ...of which eng-covered (add to MTP only, do NOT automate) | B13: =COUNTIF('Gap Analysis'!$L:$L,"Add to MTP only*")
A14: Output 2: functional gaps to AUTOMATE (QA backlog) | B14: =COUNTIF('Gap Analysis'!$L:$L,"*Automate*")
A15: ...of which QA-owned (eng cannot cover) | B15: =COUNTIF('Gap Analysis'!$L:$L,"*QA-owned*")
A16: Dev: unit-test-coverage gaps | B16: =COUNTIF('Gap Analysis'!$L:$L,"Dev:*")
A17: Cross-cutting: reconcile plan/code | B17: =COUNTIF('Gap Analysis'!$L:$L,"Reconcile*")
A19: COVERAGE TRACKER — automation of existing MTP cases
A20: Surface | B20: Automated (built) | C20: Automatable (not built) | D20: Manual only | E20: Total | F20: % Automated
A21: Login page | B21: =COUNTIFS('Automation (existing MTP)'!$B:$B,$A21,'Automation (existing MTP)'!$D:$D,"🟢*") | C21: =COUNTIFS('Automation (existing MTP)'!$B:$B,$A21,'Automation (existing MTP)'!$D:$D,"🟡*") | D21: =COUNTIFS('Automation (existing MTP)'!$B:$B,$A21,'Automation (existing MTP)'!$D:$D,"🔴*") | E21: =B21+C21+D21 | F21: =IF(E21>0,B21/E21,0)
A22: Programs List page | B22: =COUNTIFS('Automation (existing MTP)'!$B:$B,$A22,'Automation (existing MTP)'!$D:$D,"🟢*") | C22: =COUNTIFS('Automation (existing MTP)'!$B:$B,$A22,'Automation (existing MTP)'!$D:$D,"🟡*") | D22: =COUNTIFS('Automation (existing MTP)'!$B:$B,$A22,'Automation (existing MTP)'!$D:$D,"🔴*") | E22: =B22+C22+D22 | F22: =IF(E22>0,B22/E22,0)
A23: Opportunity creation | B23: =COUNTIFS('Automation (existing MTP)'!$B:$B,$A23,'Automation (existing MTP)'!$D:$D,"🟢*") | C23: =COUNTIFS('Automation (existing MTP)'!$B:$B,$A23,'Automation (existing MTP)'!$D:$D,"🟡*") | D23: =COUNTIFS('Automation (existing MTP)'!$B:$B,$A23,'Automation (existing MTP)'!$D:$D,"🔴*") | E23: =B23+C23+D23 | F23: =IF(E23>0,B23/E23,0)
A24: Opportunity List page | B24: =COUNTIFS('Automation (existing MTP)'!$B:$B,$A24,'Automation (existing MTP)'!$D:$D,"🟢*") | C24: =COUNTIFS('Automation (existing MTP)'!$B:$B,$A24,'Automation (existing MTP)'!$D:$D,"🟡*") | D24: =COUNTIFS('Automation (existing MTP)'!$B:$B,$A24,'Automation (existing MTP)'!$D:$D,"🔴*") | E24: =B24+C24+D24 | F24: =IF(E24>0,B24/E24,0)
A25: Opportunity dashboard | B25: =COUNTIFS('Automation (existing MTP)'!$B:$B,$A25,'Automation (existing MTP)'!$D:$D,"🟢*") | C25: =COUNTIFS('Automation (existing MTP)'!$B:$B,$A25,'Automation (existing MTP)'!$D:$D,"🟡*") | D25: =COUNTIFS('Automation (existing MTP)'!$B:$B,$A25,'Automation (existing MTP)'!$D:$D,"🔴*") | E25: =B25+C25+D25 | F25: =IF(E25>0,B25/E25,0)
A26: Connect workers page | B26: =COUNTIFS('Automation (existing MTP)'!$B:$B,$A26,'Automation (existing MTP)'!$D:$D,"🟢*") | C26: =COUNTIFS('Automation (existing MTP)'!$B:$B,$A26,'Automation (existing MTP)'!$D:$D,"🟡*") | D26: =COUNTIFS('Automation (existing MTP)'!$B:$B,$A26,'Automation (existing MTP)'!$D:$D,"🔴*") | E26: =B26+C26+D26 | F26: =IF(E26>0,B26/E26,0)
A27: Visit verification page | B27: =COUNTIFS('Automation (existing MTP)'!$B:$B,$A27,'Automation (existing MTP)'!$D:$D,"🟢*") | C27: =COUNTIFS('Automation (existing MTP)'!$B:$B,$A27,'Automation (existing MTP)'!$D:$D,"🟡*") | D27: =COUNTIFS('Automation (existing MTP)'!$B:$B,$A27,'Automation (existing MTP)'!$D:$D,"🔴*") | E27: =B27+C27+D27 | F27: =IF(E27>0,B27/E27,0)
A28: Invoices List page | B28: =COUNTIFS('Automation (existing MTP)'!$B:$B,$A28,'Automation (existing MTP)'!$D:$D,"🟢*") | C28: =COUNTIFS('Automation (existing MTP)'!$B:$B,$A28,'Automation (existing MTP)'!$D:$D,"🟡*") | D28: =COUNTIFS('Automation (existing MTP)'!$B:$B,$A28,'Automation (existing MTP)'!$D:$D,"🔴*") | E28: =B28+C28+D28 | F28: =IF(E28>0,B28/E28,0)
A29: Connect Messaging | B29: =COUNTIFS('Automation (existing MTP)'!$B:$B,$A29,'Automation (existing MTP)'!$D:$D,"🟢*") | C29: =COUNTIFS('Automation (existing MTP)'!$B:$B,$A29,'Automation (existing MTP)'!$D:$D,"🟡*") | D29: =COUNTIFS('Automation (existing MTP)'!$B:$B,$A29,'Automation (existing MTP)'!$D:$D,"🔴*") | E29: =B29+C29+D29 | F29: =IF(E29>0,B29/E29,0)
A30: Delivery Reminder Mails | B30: =COUNTIFS('Automation (existing MTP)'!$B:$B,$A30,'Automation (existing MTP)'!$D:$D,"🟢*") | C30: =COUNTIFS('Automation (existing MTP)'!$B:$B,$A30,'Automation (existing MTP)'!$D:$D,"🟡*") | D30: =COUNTIFS('Automation (existing MTP)'!$B:$B,$A30,'Automation (existing MTP)'!$D:$D,"🔴*") | E30: =B30+C30+D30 | F30: =IF(E30>0,B30/E30,0)
A31: App Credentials | B31: =COUNTIFS('Automation (existing MTP)'!$B:$B,$A31,'Automation (existing MTP)'!$D:$D,"🟢*") | C31: =COUNTIFS('Automation (existing MTP)'!$B:$B,$A31,'Automation (existing MTP)'!$D:$D,"🟡*") | D31: =COUNTIFS('Automation (existing MTP)'!$B:$B,$A31,'Automation (existing MTP)'!$D:$D,"🔴*") | E31: =B31+C31+D31 | F31: =IF(E31>0,B31/E31,0)
A32: Re-Learn Task | B32: =COUNTIFS('Automation (existing MTP)'!$B:$B,$A32,'Automation (existing MTP)'!$D:$D,"🟢*") | C32: =COUNTIFS('Automation (existing MTP)'!$B:$B,$A32,'Automation (existing MTP)'!$D:$D,"🟡*") | D32: =COUNTIFS('Automation (existing MTP)'!$B:$B,$A32,'Automation (existing MTP)'!$D:$D,"🔴*") | E32: =B32+C32+D32 | F32: =IF(E32>0,B32/E32,0)
A33: Microplanning | B33: =COUNTIFS('Automation (existing MTP)'!$B:$B,$A33,'Automation (existing MTP)'!$D:$D,"🟢*") | C33: =COUNTIFS('Automation (existing MTP)'!$B:$B,$A33,'Automation (existing MTP)'!$D:$D,"🟡*") | D33: =COUNTIFS('Automation (existing MTP)'!$B:$B,$A33,'Automation (existing MTP)'!$D:$D,"🔴*") | E33: =B33+C33+D33 | F33: =IF(E33>0,B33/E33,0)
A34: TOTAL | B34: =SUM(B21:B33) | C34: =SUM(C21:C33) | D34: =SUM(D21:D33) | E34: =SUM(E21:E33) | F34: =IF(E34>0,B34/E34,0)
A36: EXISTING automatable-not-built cases — do they need automating?
A37: QA-owned (UI/e2e - need automating) | B37: =COUNTIF('Automation (existing MTP)'!$G:$G,"QA-owned (UI*")
A38: Likely already eng-covered (confirm - may NOT need automating) | B38: =COUNTIF('Automation (existing MTP)'!$G:$G,"Partial*")

Sheet Gap Analysis
A1: Gap ID | B1: Surface | C1: Description | D1: Bucket | E1: Rationale/Source | F1: Priority | G1: Status | H1: Assignee | I1: Reviewer's Notes | J1: Source | K1: Eng Coverage | L1: Action
A2: GAP-MISC-01 | B2: Cross-cutting | C2: Suite covers 'revoke suspension' (test_worker_visit_verification_page_03) but MTP has no such case - add to MTP | D2: 🟡 Automatable - not yet done | E2: Reverse gap: automated behaviour missing from MTP | F2: Medium | G2: New | J2: Pass 1: MTP vs test suite | K2: N/A (hygiene/discrepancy/automation note) | L2: Reconcile (plan/code)
A3: GAP-MISC-02 | B3: Cross-cutting | C3: Suite asserts Total-row count breakdown (test_worker_list_view_05) but MTP has no matching case - add to MTP | D3: 🟡 Automatable - not yet done | E3: Reverse gap: automated behaviour missing from MTP | F3: Medium | G3: New | J3: Pass 1: MTP vs test suite | K3: N/A (hygiene/discrepancy/automation note) | L3: Reconcile (plan/code)
A4: GAP-MISC-03 | B4: Cross-cutting | C4: test_worker_visit_verification_page_01_02 and _04_05_06_07 wrap assertions in bare try/except - tests can pass silently | D4: 🟡 Automatable - not yet done | E4: Suite quality: assertions swallowed; fix in automation repo | F4: High | G4: New | J4: Pass 1: MTP vs test suite | K4: N/A (hygiene/discrepancy/automation note) | L4: Reconcile (plan/code)
A5: GAP-MISC-04 | B5: Cross-cutting | C5: Allure tags/descriptions reference an older MTP numbering (e.g. suite OLP_1 = opportunity creation vs current MTP OLP_01 = landing page) - IDs need reconciliation | D5: 🟡 Automatable - not yet done | E5: Suite/MTP ID drift discovered in pass 1 | F5: High | G5: New | J5: Pass 1: MTP vs test suite | K5: N/A (hygiene/discrepancy/automation note) | L5: Reconcile (plan/code)
A6: GAP-MISC-05 | B6: Cross-cutting | C6: MTP has duplicate case ID OD_18 (learn/deliver apps info AND inactive-workers pre-filter) | D6: 🟡 Automatable - not yet done | E6: MTP hygiene: duplicate ID to fix on sheet | F6: Medium | G6: New | J6: Pass 1: MTP vs test suite | K6: N/A (hygiene/discrepancy/automation note) | L6: Reconcile (plan/code)
A7: GAP-MISC-06 | B7: Cross-cutting | C7: MTP rows without case IDs: Connect-worker search case, OLP_05 PM-user variant, Microplanning core-metrics download case | D7: 🟡 Automatable - not yet done | E7: MTP hygiene: assign IDs so cases are trackable | F7: Medium | G7: New | J7: Pass 1: MTP vs test suite | K7: N/A (hygiene/discrepancy/automation note) | L7: Reconcile (plan/code)
A8: GAP-SRC-W-01 | B8: Visit verification page | C8: Audio attachments on visits with server-side transcription + translation (AudioAttachment.transcript/translation; audio_attachment/<pk>/transcribe endpoint) | D8: 🟡 Automatable - not yet done | E8: MISSING from MTP (WVV covers image carousel only, not audio/transcription). Src: opportunity AudioAttachment + AudioAttachmentTranscribe | F8: High | G8: New | J8: Web pass 4/5 batch 1: commcare-connect opportunity spine (urls+models) | K8: Partial (some eng coverage; confirm with eng) | L8: Add to MTP + Automate (confirm w/ eng)
A9: GAP-SRC-W-02 | B9: Visit verification page | C9: Granular verification-flag types configured per opportunity: gps, duplicate, location-radius, form-submission time window (start/end), catchment_areas, duration | D9: 🟡 Automatable - not yet done | E9: PARTIAL vs OD_7 (generic 'verification flags'). Each flag type not a case. Src: OpportunityVerificationFlags model | F9: High | G9: New | J9: Web pass 4/5 batch 1: commcare-connect opportunity spine (urls+models) | K9: Eng-covered (logic) - QA e2e only if critical journey | L9: Add to MTP only (eng-covered)
A10: GAP-SRC-W-03 | B10: Visit verification page | C10: Catchment-area based verification: import/export catchment areas (CSV) and flag visits outside the area (CatchmentArea model, import/export_catchment_area) | D10: 🟡 Automatable - not yet done | E10: MISSING from MTP. Src: opportunity CatchmentArea + import_catchment_area/export_catchment_area | F10: Medium | G10: New | J10: Web pass 4/5 batch 1: commcare-connect opportunity spine (urls+models) | K10: Partial (some eng coverage; confirm with eng) | L10: Add to MTP + Automate (confirm w/ eng)
A11: GAP-SRC-W-04 | B11: Visit verification page | C11: Form-JSON validation rules (question path == value) and per-deliver-unit flag rules (check_attachments, duration) as configurable verification checks | D11: 🟡 Automatable - not yet done | E11: MISSING from MTP. Src: FormJsonValidationRules + DeliverUnitFlagRules + delete_form_json_rule | F11: Medium | G11: New | J11: Web pass 4/5 batch 1: commcare-connect opportunity spine (urls+models) | K11: Eng-covered (logic) - QA e2e only if critical journey | L11: Add to MTP only (eng-covered)
A12: GAP-SRC-W-05 | B12: Opportunity creation | C12: auto_approve_payments opportunity setting (distinct from auto_approve_visits) - payments auto-approved without manual step | D12: 🟡 Automatable - not yet done | E12: MISSING from MTP (visit auto-approve covered, payment auto-approve not). Src: Opportunity.auto_approve_payments | F12: Medium | G12: New | J12: Web pass 4/5 batch 1: commcare-connect opportunity spine (urls+models) | K12: Eng-covered (logic) - QA e2e only if critical journey | L12: Add to MTP only (eng-covered)
A13: GAP-SRC-W-06 | B13: Opportunity creation | C13: automatic_visit_verification opportunity flag (system auto-verifies visits against rules, distinct from NM manual approve) | D13: 🟡 Automatable - not yet done | E13: PARTIAL vs MTP. Src: Opportunity.automatic_visit_verification | F13: Medium | G13: New | J13: Web pass 4/5 batch 1: commcare-connect opportunity spine (urls+models) | K13: Eng-covered (logic) - QA e2e only if critical journey | L13: Add to MTP only (eng-covered)
... A65: GAP-SRC-W-52 | B65: Connect workers page | C65: Payments tab specifics: only rows with payment_accrued>=0 and accepted=True, ordered -payment_accrued; Accrued/Total Paid/Confirm headers are currency-code-suffixed and blank when no rows; footers sum accrued and total paid; last-paid history is a lazy popup ('--' when never paid); payment import is CSV/XLSX-only and cache-locked against concurrent imports. Src: WorkerPaymentsView (~2794-2820); WorkerPaymentsTable (~1173-1229); payment_import (~784-802). | D65: 🟡 Automatable - not yet done | E65: PARTIAL vs Payment Processing_1-4 (info/pay/history/rollback happy path). | F65: Low | G65: New | J65: Web pass 7: workers-page views/tables/filters/templates deep-dive (feature/workers-web-automation) | K65: Eng-covered (logic) - QA e2e only if critical journey | L65: Add to MTP only (eng-covered)

Sheet Automation (existing MTP)
A1: Case / Gap ID | B1: Surface | C1: Description | D1: Status | E1: Detail | F1: Source | G1: Eng Coverage
A2: PLP_05 | B2: Programs List page | C2: Verify that the ‘Program Acceptance Funnel’ within a program card has all the necessary information in it | D2: 🟢 Already automated | E2: test_pm_05_06_07 | F2: Confirmed automated (pass 1) | G2: Already automated (n/a)
A3: PLP_06 | B3: Programs List page | C3: Confirm user is able to see the status of all the NMs that they invited | D3: 🟢 Already automated | E3: test_pm_05_06_07 | F3: Confirmed automated (pass 1) | G3: Already automated (n/a)
A4: PLP_07 | B4: Programs List page | C4: Verify that user is only able to create/view opportunities when at least one NM has accepted the invite | D4: 🟢 Already automated | E4: test_pm_05_06_07 | F4: Confirmed automated (pass 1) | G4: Already automated (n/a)
A5: Opp_create_04 | B5: Opportunity creation | C5: Verify user is able to create on opportunity as PM user | D5: 🟢 Already automated | E5: test_olp_01_02_03 | F5: Confirmed automated (pass 1) | G5: Already automated (n/a)
A6: Opp_create_05 | B6: Opportunity creation | C6: Verify user is able to land on the payment unit page | D6: 🟢 Already automated | E6: test_olp_01_02_03 | F6: Confirmed automated (pass 1) | G6: Already automated (n/a)
A7: Opp_create_21 | B7: Opportunity creation | C7: Verify user is able to land on the Budget page | D7: 🟢 Already automated | E7: test_olp_01_02_03 | F7: Confirmed automated (pass 1) | G7: Already automated (n/a)
A8: Opp_create_28 | B8: Opportunity creation | C8: Verify user is able to create the opportunity successfully | D8: 🟢 Already automated | E8: test_olp_01_02_03 | F8: Confirmed automated (pass 1) | G8: Already automated (n/a)
A9: OLP_11 | B9: Opportunity List page | C9: Verify "Status" field drop down contains: - Active - Ended - Inactive | D9: 🟢 Already automated | E9: test_olp_11 | F9: Confirmed automated (pass 1) | G9: Already automated (n/a)
A10: OD_2 | B10: Opportunity dashboard | C10: Confirm user can see the opportunity details on the dashboard page | D10: 🟢 Already automated | E10: test_olp_04 | F10: Confirmed automated (pass 1) | G10: Already automated (n/a)
A11: OD_4 | B11: Opportunity dashboard | C11: Verify user see the all the information related to the deliveries under "Service Deliveries" section | D11: 🟢 Already automated | E11: test_olp_05 | F11: Confirmed automated (pass 1) | G11: Already automated (n/a)
A12: OD_5 | B12: Opportunity dashboard | C12: Verify user can see all the payment related information under "Payments to Workers" section | D12: 🟢 Already automated | E12: test_olp_06 | F12: Confirmed automated (pass 1) | G12: Already automated (n/a)
... A339: Connect_worker_13 | B339: Connect workers page | C339: Verify user is able to delete not-found users (Delete affordance; not executed to preserve seed) | D339: 🟢 Already automated | E339: test_worker_lifecycle.py::test_connect_worker_13_not_found_deletable | F339: Connect Workers Batch C - Anshu data 2 (Worker_Lifecycle_Automation, 2026-09-10) | G339: Already automated (n/a)

Sheet  Test Tracker
B1: CCC Web Platform [Master] | F1: Keys
F2: Pass | H2: Passed steps of Test Case
F3: Fail | H3: Failed steps of Test Case
F4: N/A | H4: Not applicable to your testing
F5: Blocking | H5: Failed and is a critical feature or cannot proceed with testing
A6: Name of Tester | B6: Start Date | C6: End Date | F6: Unanswered | H6: Unanswered/ blank test cases
A9: Tab | B9: Execution Status | C9: Duration (In Hours) | D9: Comments (if any) | F9: Case Results (if none, displays as 0) | K9: Total | M9: Ticket Summaries (if none, displays as #N/A)
A10: =sheetName(2) | F10: =countif(INDIRECT("'"&A10&"'!"&"F2:F1000"), "Pass") | G10: =countif(INDIRECT("'"&A10&"'!"&"F2:F1000"), "Fail") | H10: =countif(INDIRECT("'"&A10&"'!"&"F2:F1000"), "N/A") | I10: =countif(INDIRECT("'"&A10&"'!"&"F2:F1000"), "Blocking") | J10: =countif(INDIRECT("'"&A10&"'!"&"F2:F1000"), "") | K10: =sum(F10:J10) | M10: =IFERROR(__xludf.DUMMYFUNCTION(" TRANSPOSE(UNIQUE( FILTER( INDIRECT(""'""&A10&""'!""&""G3:G200"") , NOT(ISBLANK(INDIRECT(""'""&A10&""'!""&""G3:G200""))) ) ))"),"#N/A")
A11: =sheetName(3) | F11: =countif(INDIRECT("'"&A11&"'!"&"F2:F1000"), "Pass") | G11: =countif(INDIRECT("'"&A11&"'!"&"F2:F1000"), "Fail") | H11: =countif(INDIRECT("'"&A11&"'!"&"F2:F1000"), "N/A") | I11: =countif(INDIRECT("'"&A11&"'!"&"F2:F1000"), "Blocking") | J11: =countif(INDIRECT("'"&A11&"'!"&"F2:F1000"), "") | K11: =sum(F11:J11)
A12: =sheetName(4) | F12: =countif(INDIRECT("'"&A12&"'!"&"F2:F1000"), "Pass") | G12: =countif(INDIRECT("'"&A12&"'!"&"F2:F1000"), "Fail") | H12: =countif(INDIRECT("'"&A12&"'!"&"F2:F1000"), "N/A") | I12: =countif(INDIRECT("'"&A12&"'!"&"F2:F1000"), "Blocking") | J12: =countif(INDIRECT("'"&A12&"'!"&"F2:F1000"), "") | K12: =sum(F12:J12)
A13: =sheetName(5) | F13: =countif(INDIRECT("'"&A13&"'!"&"F2:F1000"), "Pass") | G13: =countif(INDIRECT("'"&A13&"'!"&"F2:F1000"), "Fail") | H13: =countif(INDIRECT("'"&A13&"'!"&"F2:F1000"), "N/A") | I13: =countif(INDIRECT("'"&A13&"'!"&"F2:F1000"), "Blocking") | J13: =countif(INDIRECT("'"&A13&"'!"&"F2:F1000"), "") | K13: =sum(F13:J13)
A14: =sheetName(3) | F14: =countif(INDIRECT("'"&A14&"'!"&"F2:F1000"), "Pass") | G14: =countif(INDIRECT("'"&A14&"'!"&"F2:F1000"), "Fail") | H14: =countif(INDIRECT("'"&A14&"'!"&"F2:F1000"), "N/A") | I14: =countif(INDIRECT("'"&A14&"'!"&"F2:F1000"), "Blocking") | J14: =countif(INDIRECT("'"&A14&"'!"&"F2:F1000"), "") | K14: =sum(F14:J14)
A15: =sheetName(7) | F15: =countif(INDIRECT("'"&A15&"'!"&"F2:F1000"), "Pass") | G15: =countif(INDIRECT("'"&A15&"'!"&"F2:F1000"), "Fail") | H15: =countif(INDIRECT("'"&A15&"'!"&"F2:F1000"), "N/A") | I15: =countif(INDIRECT("'"&A15&"'!"&"F2:F1000"), "Blocking") | J15: =countif(INDIRECT("'"&A15&"'!"&"F2:F1000"), "") | K15: =sum(F15:J15)
A16: =sheetName(8) | F16: =countif(INDIRECT("'"&A16&"'!"&"F2:F1000"), "Pass") | G16: =countif(INDIRECT("'"&A16&"'!"&"F2:F1000"), "Fail") | H16: =countif(INDIRECT("'"&A16&"'!"&"F2:F1000"), "N/A") | I16: =countif(INDIRECT("'"&A16&"'!"&"F2:F1000"), "Blocking") | J16: =countif(INDIRECT("'"&A16&"'!"&"F2:F1000"), "") | K16: =sum(F16:J16)
A17: =sheetName(9) | F17: =countif(INDIRECT("'"&A17&"'!"&"F2:F1000"), "Pass") | G17: =countif(INDIRECT("'"&A17&"'!"&"F2:F1000"), "Fail") | H17: =countif(INDIRECT("'"&A17&"'!"&"F2:F1000"), "N/A") | I17: =countif(INDIRECT("'"&A17&"'!"&"F2:F1000"), "Blocking") | J17: =countif(INDIRECT("'"&A17&"'!"&"F2:F1000"), "") | K17: =sum(F17:J17)
A18: =sheetName(10) | F18: =countif(INDIRECT("'"&A18&"'!"&"F2:F1000"), "Pass") | G18: =countif(INDIRECT("'"&A18&"'!"&"F2:F1000"), "Fail") | H18: =countif(INDIRECT("'"&A18&"'!"&"F2:F1000"), "N/A") | I18: =countif(INDIRECT("'"&A18&"'!"&"F2:F1000"), "Blocking") | J18: =countif(INDIRECT("'"&A18&"'!"&"F2:F1000"), "") | K18: =sum(F18:J18)
A19: =sheetName(11) | F19: =countif(INDIRECT("'"&A19&"'!"&"F2:F1000"), "Pass") | G19: =countif(INDIRECT("'"&A19&"'!"&"F2:F1000"), "Fail") | H19: =countif(INDIRECT("'"&A19&"'!"&"F2:F1000"), "N/A") | I19: =countif(INDIRECT("'"&A19&"'!"&"F2:F1000"), "Blocking") | J19: =countif(INDIRECT("'"&A19&"'!"&"F2:F1000"), "") | K19: =sum(F19:J19)
A20: =sheetName(12) | F20: =countif(INDIRECT("'"&A20&"'!"&"F2:F1000"), "Pass") | G20: =countif(INDIRECT("'"&A20&"'!"&"F2:F1000"), "Fail") | H20: =countif(INDIRECT("'"&A20&"'!"&"F2:F1000"), "N/A") | I20: =countif(INDIRECT("'"&A20&"'!"&"F2:F1000"), "Blocking") | J20: =countif(INDIRECT("'"&A20&"'!"&"F2:F1000"), "") | K20: =sum(F20:J20)
A21: =sheetName(13)

Sheet Login page
A1: Test Case ID | B1: Description | C1: Steps | D1: Outcome | E1: Status (Pass/Fail) | F1: QA Ticket | G1: Comments
A2: Login Page
A3: Login 1 | B3: Verify user sees the username and password fields on the login page | C3: 1. Click on the link: https://connect-staging.dimagi.com/accounts/login | D3: - User should see the two fields for password and username on the login page - User should be able to input any value in the fields - User should see a Login button - User should also see Reset password button
A4: Login 2 | B4: Verify the fields accept the correct inputs only | C4: 1. Navigate to CCC login page 2. enter the username and password | D4: - The username field should show the appropriate error messages if user enters email in wrong format - We should display placeholder text in the fields for users
A5: Login 3 | B5: Verify user can login by entering the correct credentials | C5: cont to above TC - Click on login button | D5: - User should be able to login with the right creds - User should not be able to login with wrong credentials
A6: Login 4 | B6: User should be able to login using CommCare HQ login option i.e. SSO | C6: 1.Navigate to CCC web login page 2.Click on login with commcare 3. Authorize the commcare 4. You will be login to CCC web
A7: Login 5 | B7: Verify if the user see a sign-up option | C7: 1. On CCC web login page, click on the sign up link at the bottom 2. Create a CCC account | D7: - User should be taken to the sign up page on clicking the sign up button
A8: Login 6 | B8: Ensure user is unable to login using the wrong credentials on the login page | C8: 1. Go to CCC login page 2. Enter wrong username and password 3. Click login button | D8: - User should see an appropriate error message if they try to login using wrong creds
A9: Login 7 | B9: User should be prompted to login on HQ if they use Login via CommCare HQ option | C9: Cont to above TC - On account creation page, Click on Signup with commcare HQ | D9: - User should be taken to HQ login page if they try to login using CommCare HQ and they are not logged in on HQ
A10: Login 8 | B10: User should be able to reset password for their account | C10: 1. Navigate to CCC web UI login page 2. Click on reset password link | D10: On clicking the reset button, user should be able to initiate the reset password flow to reset the account password
A11: Login 9 | B11: User should be able to login with the new password | C11: 1. Login with new password into the CCC web UI | D11: User should be able to login with the new password after resetting the pw

Sheet Programs List page
A1: Test Case ID | B1: Description | C1: Steps | D1: Outcome | E1: Status (Pass/Fail) | F1: QA Ticket | G1: Comments
A2: PLP_01 | B2: Verify user is able to create new program | C2: 1. Login to CCC web UI as PM user 2. Click on +Add Programs button 3. Fill the following details: - Name - Description - Select delivery type - Budget - Currency - Country - Start date - End date 4. Click submit | D2: - User is able to create new program successfully - Created program is shown on the programs list page | E2: Pass | G2: Automated (setup flow: create_program)
A3: PLP_02 | B3: Confirm that the user is able to invite NMs to the program that they created | C3: cont from above TC - Invite NM user to a program | D3: User should be able to invite the NMs to the programs | E3: Pass | G3: Automated (setup flow: invite_network_manager)
A4: PLP_03 | B4: Confirm PM sees all the programs on the dashboard screen | C4: 1. Log in to CCC web UI 2. Click on the hamburger option present on left side 3. Select the programs option | D4: - PM user should be able to view all the programs as separate cards - The programs should be sorted by the most recent program creation date - Each program card should display the relevant summary to the PM: i) Program description ii) Start and End date iii) Budget allocated | E4: Pass | G4: Automated: test_plp_list_page (card summary fields)
A5: PLP_04 | B5: Confirm user is able to select any of the programs from the list | D5: - User should be able to select any program from the list - User should be able to perform any of the following action after selecting the program i) View the ‘Program Acceptance Funnel’ ii) View the Status of the Program by clicking the ‘View Status’ button and expanding out more information iii) Invite new Network Managers using the Invite button | E5: Pass | G5: Automated: test_plp_list_page (View Status expand)
A6: PLP_05 | B6: Verify that the ‘Program Acceptance Funnel’ within a program card has all the necessary information in it | C6: 1. Login to CCC web UI 2. Navigate to programs list page 3. Click on view status button on the program details | D6: The ‘Program Acceptance Funnel’ should have the following information - Number of Network Managers Invited - Number Applied - Number Accepted | E6: Pass | G6: Automated: test_plp_list_page (acceptance_funnel)
A7: PLP_06 | B7: Confirm user is able to see the status of all the NMs that they invited | C7: 1. Login to CCC web UI 2. Navigate to programs list page 3. Click on view status button on the program details | D7: - User should be able to see the status of the NMs invited by clicking the 'View Status' button and expand the list of Network Managers - The list should display all the NM Orgs under a Program should be listed in alphabetical order for consistency of view - For each NM, user should be able to see the status as Invited, Applied or Accepted | E7: Pass | G7: Automated: test_plp_list_page (nm_application_statuses)
A8: PLP_07 | B8: Verify that user is only able to create/view opportunities when at least one NM has accepted the invite | C8: 1. Login to CCC web UI 2. Navigate to programs list page 3. Click on view status button on the program details 4. Click on create opportunity for creating new opportunity 5. Click on view opportunity for viewing the opportunities | D8: Only when an NM is in accepted status, user should be able to take either of the following actions as a next step - Create Opportunity - View Opportunity | E8: Pass | G8: Automated (setup flow: Create/View Opportunity when accepted)
A9: PLP_08 | B9: Verify on landing the Program page, user is able work on the program | D9: When the user land on the Program page,they should be able to perform any of the two actions: - Reviewing visits approved by NMs - Paying invoices | G9: Not on list page; = Recent Activities destinations (link targets asserted)
A10: PLP_09 | B10: Verify on landing the Opportunity page, user is able check the performance of the program | D10: User should be able to compare the performance of different NMs through the following fields - Active Workers - Deliveries - Approved Deliveries - Earnings User should be able to go through the opportunity dashboard as to check how the workers are performing | G10: Covered via Opportunity List PM columns (test_olp_list_page)
A11: PLP_10 | B11: Confirm user see following information for any program in the list - Program Name - Program Manager Org Name -Delivery Type - Program Start Date - Program End Date - Status: Invited or Applied or Accepted | D11: - User should see all the information for the program in the list - The accepted status appears after Opportunity creation, so confirm that as well | E11: Pass | G11: Automated: test_plp_list_page (card summary fields)
A12: PLP_11 | B12: User should be able to click on "View Opportunities" button in a program to view opportunities | C12: 1.Login to CCC web UI 2. Navigate to program list page 3. Click on view status dropdown on program details section 4. Click on view opportunities button | D12: - If there are any opportunities in a program, user should be able to see the list of all opportunities by clicking the button | E12: Pass | G12: Automated: test_plp_list_page (click_view_opportunities)
A13: PLP_12 | B13: On the right panel, user should see the following three options - Pending Review - Pending Payment - Inactive Workers | D13: - On clicking the category, the Program Name/Opportunities are listed based on descending order of the relevant metric - The number of items in the list should be restricted to 3 per category | E13: Pass | G13: Automated: test_plp_list_page (Recent Activities categories + rows)
A14: PLP_14 | B14: Verify when user clicks on 'Pending Payments', they see a list of opportunities with pending payments | C14: 1.Login to CCC web UI 2. Navigate to program list page 3. Click on the opportunity under pending payments section | D14: - When user clicks on the pending payments option on the right pane, user should see a list of opportunities with pending payments - When user clicks on an Opportunity under ‘Pending Payments’, they should jump to the Worker List page with the payment tab open | E14: Pass | G14: Automated (link target asserted): Recent Activities row hrefs
A15: PLP_15 | B15: Verify user can see all the workers who have not delivered any visits or not completed any learning in last 3 days when they click on Inactive Workers option | C15: 1.Login to CCC web UI 2. Navigate to program list page 3. Click on the opportunity under inactive workers section | D15: - When user clicks on 'Inactive Workers' option, user should see a list of opportunities with inactive workers - When user clicks on an Opportunity under ‘Inactive Workers’, they should jump to the Worker List page with the filtered list of workers who have not delivered any visits or not completed a learning module in the last 3 days. | E15: Pass | G15: Automated (link target asserted): Recent Activities row hrefs
A16: PLP_16 | B16: Confirm when user clicks on Apply button for any program, the PM can see the user have applied | C16: 1. Login to CCC web UI as NM user 2. Navigate to programs list page 3. Click on apply for a program 4. Switch to PM user account 5. Verify on programs list page | D16: - Program manager should be able to see if someone applies for a program | E16: Pass | G16: Automated (setup flow: apply_to_program)
A17: PLP_17 | B17: Verify that the user can view opportunities associated with a specific NM user by clicking the 'View Opportunities' button on the Program List page. [PM user] | C17: 1. Login to CCC web UI 2. Navigate to program list page 3. Click on view status dropdown for any program 4. Click on view opportunities button for any NM user under a program | D17: - User is able to see the opportunities related to specific NM user | E17: Pass | G17: Automated: test_plp_list_page (View Opportunities)

Sheet Opportunity creation
A1: Test Case ID | B1: Description | C1: Steps | D1: Outcome | E1: Status (Pass/Fail) | F1: QA Ticket | G1: Comments
A2: Opp_create_01 | B2: Confirm user is not able to create an opportunity as NM user | D2: -User is not able to create an opportunity as NM user
A3: Opp_create_02 | B3: Verify user is not able to create non managed opp as PM user | D3: - User is not able to create a non managed Opportunity as PM user
A4: Opp_create_03 | B4: Verify all the non managed opp are linked to legacy test program | D4: - All non managed opp are migrated to managed opps and linked legacy test program
A5: Opp_create_04 | B5: Verify user is able to create on opportunity as PM user | C5: 1. Login to CCC web UI 2. Navigate to program list page 3. Under a program click on view status >> Under NM user details click on create opportunity button 4. Fill all the required details - Select the NM user from drop down - Enter name, short description and Description - Select the currency from dropdown - Select the required server from the "HQ server" dropdown - Select the api key from "API key" dropdown - Under apps section, select the domain and learn/deliver apps from their respective dropdowns - Enter learn app description and learn app passing score 5. Click submit | D5: - User should land on the create opportunity page - When hq server is selected, the api keys related to the selected hq server are dispalyed in the dropdown - Domain dropdowns displays the domains that related to the selected api key - Apps that belongs to the selected domain are displayed in the dropdown
A6: Opp_create_05 | B6: Verify user is able to land on the payment unit page | C6: Continue to above TC 6. On payment unit page, Click Add payment unit 7. payment unit create section is appeared 8. Fill all the required fileds - Enter payment name and description - Enter the amount that will accured per visit - Enter amount for org per visit - Enter the number of Max.total visits that a worker should be able to submit overall - Enter number of Max.daily visits that a work should be able to submit per day - Enter start and end date Under required details section, select the deliver units [ Payment is accured only when selected forms are submitted and approved] 9. Click "Setup budget" | D6: - User should land on the payment unit page - USer should be able to add payment units for an opportunity
A7: Opp_create_06 | B7: Verify user can set Org Pay at the payment unit level. | C7: 1. Login to CCC web UI as PM user 2. Create a managed opportunity 3. Click submit 4. On payment unit page, verify we can see org pay field 5. Enter the amount and fill all the fields 6. Set up budget | D7: - User should be to set Org pay at payment unit level
A8: Opp_create_07 | B8: Verify Org Pay can be configured independently for each payment unit within the same opportunity. | C8: 1.Login as PM user 2.Create opportunity with multiple payment units 3.Set Org Pay for Payment Unit 1 (e.g., 50) 4.Set a different Org Pay for Payment Unit 2 (e.g., 75) 5. Click save | D8: - User should configure org pay independently for each payment
A9: Opp_create_08 | B9: Verify editing Org Pay for one payment unit does not affect others. | C9: 1.Open an existing opportunity with multiple payment units 2.Edit Org Pay of Payment Unit 1 3.Save and refresh 4.Verify Org Pay of other units | D9: - Editing the payment unit should not effect the other payment units
A10: Opp_create_09 | B10: Verify payment units can be configured with 0 Org Pay | C10: 1.Add a payment unit 2. Set Org Pay = 0 3. Save changes | D10: - User should be able to configure zero org pay payments - User should be able to submit the forms for zero org payment units
A11: Opp_create_10 | B11: Verify valid error message is displayed when decimal values are given in amount field | C11: 1. Login to CCC web UI 2. Create a managed opportunity >> click submit 3. On paymnet unit page, enter org pay as decimal 4. click save | D11: - User should not be able to save the payment unit - User should see the following error message: "Please enter a valid value. Nearest values are"
A12: Opp_create_11 | B12: Verify valid error message is displayed when long int values are entered | C12: 1. Login to CCC web UI 2. Create a managed opportunity >> click submit 3. On paymnet unit page, enter org pay as Long int 4. click save | D12: - User should not be able to save the payment unit - User should see the following error message: "Ensure this value is less than or equal to 2147483647".
A13: Opp_create_12 | B13: Verify valid error message is displayed when negative values are entered | C13: 1. Login to CCC web UI 2. Create a managed opportunity >> click submit 3. On paymnet unit page, enter org pay as negative values 4. click save | D13: - User should not be able to save the payment unit - User should see the following error message: "Value must be greater than or equal to 0".
A14: Opp_create_13 | B14: Verify user can't enter the special characters in the field | C14: 1. Login to CCC web UI 2. Create a managed opportunity >> click submit 3. On paymnet unit page, enter org pay as special characters | D14: - User should not be able to enter any special characters in org pay field
A15: Opp_create_14 | B15: Verify total opportunity budget reflects the sum of Org Pay across all payment units. | C15: 1. Login as PM user 2. Create opportunity with multiple payment units 3. Enter Org Pay for each payment unit 4. Save opportunity 5. Navigate to opportunity dashboard and check total budget | D15: - Total budget should get update properly
A16: Opp_create_15 | B16: Verify recalculation happens correctly when Org Pay is updated | C16: 1. Open an existing opportunity with multiple payment units 2. Edit Org Pay for one payment unit 3. Save changes 4.Refresh page/dashboard and check total budget | D16: Total opportunity budget is updated correctly based on new Org Pay
... A29: Opp_create_28 | B29: Verify user is able to create the opportunity successfully | C29: 1. Logn to CCC web UI as PM user 2. Navigate to opp list page 3. Navigate to program list page 4. Under a program click on view status >> Under NM user details click on create opportunity button 5. Create an opportunity | D29: -User should be able to create the opportunity successfully and able to land on the opportunity dashboard of the newly created opportunity

Sheet Opportunity List page
A1: Test Case ID | B1: Description | C1: Steps | D1: Outcome | E1: Status (Pass/Fail) | F1: QA Ticket | G1: Comments
A2: OLP_01 | B2: Confirm user lands on the Opportunity list page on successful login | C2: 1. Login to the CCC web UI using correct username and password https://connect-staging.dimagi.com/accounts/login | D2: - User should land on the opportunity list page and see all the programs user's been invited to - The order of the list should be such that the newest invitation be at top - Opportunities should be listed in the order of start date | E2: Pass | G2: Automated: test_olp_list_page (verify_loaded)
A3: OLP_02 | B3: Confirm user is not able to create an opportunity as NM user | D3: -User is not able to create an opportunity as NM user | E3: Pass | G3: Automated: test_olp_list_page NM (managed opportunity-init returns 403 for NM; uses seeded program_id)
A4: OLP_04 | B4: User should be able to land on the Opportunity list page when they select the option from the right pane | C4: 1. Log in to CCC web UI 2. Click on the hamburger option present on left side 3. Select the opportunities option | D4: - User should land on the opportunity list page and should see all the opportunities created by the user - If there are no opportunities created, user should see an empty list and "Create Opportunity" option on the page - User should also see "Add New" button | E4: Pass | G4: Automated: test_olp_list_page (landing)
A5: OLP_05 | B5: User should see the following information for any opportunity on the page when login with network manager - Test or Real - Status - Program Name - Start & End Date - Pending Invites - Inactive connect workers - Pending Approvals - Payment Due | C5: 1. Log in to CCC web UI 2. Navigate to opportunity list page | D5: - The columns should be displayed and give off the following info: i) Status: Active, Inactive or Ended (past end date) ii) Pending Invites: Invitations sent successfully to workers and not accepted yet iii) Inactive workers: No form submission in 3 days in Learn or Deliver app iv) Deliveries pending approval v) Payments due to workers - The Opportunities should be listed in the following order of sequence: Active on top Earliest Start Date Earliest End Date - User should be able to sort the list by clicking on any column header | E5: Pass | G5: Automated: test_olp_list_page (PM+NM columns, sortable headers)
B6: User should see the following information for any opportunity on the page when login with program manager - Test or Real - Status - Program Name - Start & End Date - Active connect workers - Total deliveries - Verified deliveries - Worker Earnings | C6: 1. Log in to CCC web UI 2. Navigate to opportunity list page | D6: - The columns should be displayed and give off the following info: i) Status: Active, Inactive or Ended (past end date) ii) Active workers iii) Count of total deliveries iv) Count of verified deliveries v) Deliveries pending approval vi) Payment amount earned by workers - The Opportunities should be listed in the following order of sequence: Active on top Earliest Start Date Earliest End Date - User should be able to sort the list by clicking on any column header
A7: OLP_06 | B7: Confirm user can filter the opportunities on the basis of Status | C7: 1. Login to CCC web UI 2. Navigate to opportunity list page 3. Click on the filter icon 4. Apply neccessary filters and click Apply | D7: User should be able to filter the opportunities on the basis of Status by selecting from the Opportunity and Status dropdown - Opportunity Dropdown All Test Live - Status Dropdown All Inactive Active Ended | E7: Pass | G7: Automated: test_olp_list_behaviour (status filter)
A8: OLP_07 | B8: Confirm user is able to navigate to different pages using the pagination | C8: 1. Login to CCC web UI 2. Navigate to opportunity list page 3. Select the rows per page 4. Navigate through the pages | D8: - The opportunity list page should only list the number of opportunities selected by the user for "Rows per page" - User should be able to navigate forward backwards using the pagination arrows | E8: Pass | G8: Automated: test_olp_list_behaviour (pagination; skips when <=20 opps)
A9: OLP_08 | B9: Confirm users can land on the opportunity page, if they select any opportunity from the list | C9: 1. Login to CCC web UI 2. Navigate to opportunity list page 3. Click on any opportunity | E9: Pass | G9: Automated: test_olp_list_page (open_opportunity)
A10: OLP_09 | B10: Verify Filters pop up modal is displayed by clicking on the filters icon on opp list page | C10: 1. Login to CCC web UI 2. Navigate to opportunity list page 3. Click on the filters icon | D10: Filters pop up modal should be displayed containing following fileds: - Is test - Status - Program (Visible only to PM users) | E10: Pass | G10: Automated: test_olp_list_page (filter modal fields)
A11: OLP_10 | B11: Verify "Is test" field drop down contains: - Yes - No | C11: 1. Login to CCC web UI 2. Navigate to opportunity list page 3. Click on the filters icon 4. Click on "Is Test" field | D11: - Test opportunities should be displayed when 'yes' is selected - Non test opportunities should be displayed when 'no' is selected | E11: Pass | G11: Automated: test_olp_list_page (is_test options)
A12: OLP_11 | B12: Verify "Status" field drop down contains: - Active - Ended - Inactive | C12: 1. Login to CCC web UI 2. Navigate to opportunity list page 3. Click on the filters icon 4. Click on "Status" field | D12: - Active opportunities should be displayed when active is selected - Ended opportunities should be displayed when ended is selected - Inactive opportunities should be displayed when inactive is selected | E12: Pass | G12: Automated: test_olp_list_page (status options)
A13: OLP_12 | B13: Verify "Program" field drop down contains list of all programs [PM user] | C13: 1. Login to CCC web UI 2. Navigate to opportunity list page 3. Click on the filters icon 4. Click on "Program" field | D13: - Verify the drop down should contain the list of all programs - Opportunities that are part of selected program should be displayed | E13: Pass | G13: Automated: test_olp_list_page (program options, PM)
A14: OLP_13 | B14: Verify on the clicking on apply button, filters are applied | C14: 1. Login to CCC web UI 2. Navigate to opportunity list page 3. Click on the filters icon 4. Apply few filters and click Apply | D14: - Selected filters should be applied on opportunities - Number of filters selected should be displayed on the filters icon | E14: Pass | G14: Automated: test_olp_list_behaviour (apply + filter badge)
A15: OLP_14 | B15: Verify user is able to select multiple options in status fileld | C15: 1. Login to CCC web UI 2. Navigate to opportunity list page 3. Click on the filters icon 4. Click on "Status field" 5. Select multiple options under status filed 6. Click on Apply | D15: - Multiple filters selected should be applied on the opportunities | E15: Pass | G15: Automated: test_olp_list_behaviour (multi-select status)
A16: OLP_15 | B16: Verify user is able to select multiple options in programs filed[PM user] | C16: 1. Login to CCC web UI 2. Navigate to opportunity list page 3. Click on the filters icon 4. Click on programs field 5. Select multiple programs under programs filed 6. Click on Apply | D16: - Opportunities related to the selected programs should be displayed | E16: Pass | G16: Automated: test_olp_list_behaviour (program filter)
A17: OLP_16 | B17: Verify Navigating away and back to a page should preserve the filters applied on the page | C17: 1. Login to CCC web UI 2. Navigate to opportunity list page 3. Apply filters 4. Navigate away and back by using arrow | D17: - Applied filters should be preserved when user navigate away and back | E17: Pass | G17: Automated: test_olp_list_behaviour (filter persistence)
A18: OLP_17 | B18: Verify user is able to see the following buttons by clicking on the three dots at the end of opportunity details - "view opportunites" - "view connect workers" - View Invoices | C18: 1. Login to CCC web UI 2. Navigate to opp list page 3. Click on the 3 dots option present at the end of opportunity details | D18: - User should be able to see the following details: View opportunites View connect workers View Invoices | E18: Pass | G18: Automated: test_olp_list_page (kebab_options)
A19: OLP_18 | B19: Verify user is able to land on the opportunity dashboard by clicking on the "view opportunity" button | C19: Cont to above TC - Click on view opportunities option | D19: - User should be land on opportunity dashboard | E19: Pass | G19: Automated: test_olp_list_behaviour (kebab View Opportunity target)
A20: OLP_19 | B20: Verify user is able to land on the connect workers by cliicking on the "view connect workers" button | C20: Cont to OLP_20 - Click on view connect workers option | D20: - User should be land on Connect workers page | E20: Pass | G20: Automated: test_olp_list_behaviour (kebab View Connect Workers target)
A21: OLP_20 | B21: Verify user is able to land on the invoices page by cliicking on the "view invoices" button | C21: Cont to OLP_20 - Click on view invoices option | D21: - User should be land on invoices page | E21: Pass | G21: Automated: test_olp_list_behaviour (kebab View Invoices target)
... A29: OLP_30 | B29: Verify when user click on the amount under "Worker Earnings" column, user should land on the payment tab [PM user] | C29: 1. Login to CCC web UI 2. Navigate to opportunity list page 3. Click on the count under "Worker Earnings" column | D29: - User should be able to land on the payments tab | E29: Pass | G29: Automated: test_olp_list_behaviour (Worker Earnings drill-down)

Sheet Opportunity dashboard
A1: Test Case ID | B1: Description | C1: Steps | D1: Outcome | E1: Status (Pass/Fail) | F1: QA Ticket | G1: Comments
A2: OD_1 | B2: Confirm user lands on the opportunity dashboard page when they select any opportunity | C2: 1. Login to CCC web UI 2. Navigate to opportunity list page 3. Click on any opportunity | D2: - User should land on the opportunity dashboard
A3: OD_2 | B3: Confirm user can see the opportunity details on the dashboard page | D3: User should be able to all the necessary correct information - Start & End Date - Total Workers invited - Count of inactive workers in the past 3 days - Total Deliveries - View progress map - Tasks assigned to connect workers - Audit opportunity - Total payment earned and due User should also be able to see the progress funnel and delivery progress graphs
A4: OD_3 | B4: Confirm user can analyse how many workers were actually invited and continuing to deliver | C4: 1. Login to CCC web UI 2.Go to opportunity list page 3. Select any opportunity 4. Navigate to opportunity dashboard 5. Verify count for connnect workers - invited, Inactive, tasks assigned to workers | D4: User should see following information under workers section - Connect workers button: User should land on connect workers page upon clicking on connect workers button - Inactive last 3 days - Tasks assigned to connect workers
A5: OD_4 | B5: Verify user see the all the information related to the deliveries under "Service Deliveries" section | C5: 1. Login to CCC web UI 2.Go to opportunity list page 3. Select any opportunity 4. Navigate to opportunity dashboard 5. Click on "services deliverd" button 6. You will land on the delivery tab | D5: Following information should be getting displayed under Deliveries section in boxes and progress bars: - Status - Name - Last delivery timestamp that updates dynamically - Delivery progress - Payment unit - Delivered - Approved - Rejected
A6: OD_5 | B6: Verify user can see all the payment related information under "Payments to Workers" section | C6: 1. Login to CCC web UI 2.Go to opportunity list page 3. Select any opportunity 4. Navigate to opportunity dashboard 5. Click on "payments earned" button 6. You will land on the payments tab | D6: Following information should be displayed under payments section in boxes and progress: - Last Payment date - Total Budget (should match top panel number) - Worker Earned amount - Worker Payments due Following details should be shown under payments tab: - Status - Name - Last active - Accrued - Total Paid - Last Paid - Confirm
A7: OD_6 | B7: Confirm user can click on the hamburger option on the opportunity dashboard page and see different options | C7: 1. Login to CCC web UI 2.Go to opportunity list page 3. Select any opportunity 4. Navigate to opportunity dashboard 5. Click on the hamburger option | D7: User should see the following options when they click on the hamburger option - Edit opportunity - Add payment unit - View Invoices - Catchment Areas - Add Workers - Add Worker Budget - Verification Flags - Send Message - Configure task types
A8: OD_7 | B8: Confirm user is taken to the verification flag on selecting "Verification Flags" option | C8: Continue from above TC - Select verification flags from hamburger option | D8: - User should see the verification flags page, when they select "Verification Flags" option - Program Manager should see all the verification flags and should be able to edit/configure them Following verification rules are shown: - Start and end time of vists submission - Minium time should be taken to submit a visit - Form validation rules If submitted visit doesn't satisfy the above verification rules, automatically visit should get rejected
A9: OD_8 | B9: Confirm user is able to send message using send message option | C9: 1. Login to CCC web Ui 2. Go to opp dahsboard 3.Click on hamburger option >> send message 4. Select the users you want to send message 5. Enter the message >> Click confirm | D9: - User should be able to send message to send message - User should recieve push notification in mobile - User should see a message sent in notification history | G9: AUTOMATION: Web part automated (Send Message page reachable) - PR #38, tests/test_opd_budget.py::test_opd_08_send_message_page. MOBILE HALF NOT AUTOMATED (push notification on device + notification history) - out of web/Playwright scope; needs a Maestro mobile hybrid test (device signs in as the enrolled worker after the web send, like TASKING_HYBRID / test_e2e_relearn_lifecycle). Prereqs: enrolled mobile worker on the opp, BrowserStack/Appium, a new Maestro flow; runs @on_demand.
A10: OD_9 | B10: Confirm user is redirected to Add Workers page when they click on the Add Workers option | C10: Two ways to add connect workers: 1. Navigate to opp dashboard Click on hamburger options Select Add connect workers option 2.On opp dashboard, select connect workers button Select "+" on connect workers tab | D10: - User should be redirected to a new page where they should see an input field and add workers to the opportunity | G10: AUTOMATION: Automated - PR #38, test_opd_budget.py::test_opd_09_add_connect_workers_redirect (redirects to user_invite; #id_users present).
A11: OD_10 | B11: Verify user is able to add budget for existing workers using add budget option | C11: 1. Login to CCC web UI 2. Navigate to Opp dashboard >> Hamburger option 3. Click on Add budget 4. Under existing workers tab, select the workers you want to add the budget 5. Enter the no.of visits and select to increase or decerase the visits 6. Extend the opportunity date if you want | D11: - User should be able to add the budget and visits for exisiting workers | G11: AUTOMATION: Automated - PR #38, test_opd_budget_mutations.py::test_opd_10 (increase visits; Max Visits reflects; mutate-then-revert on the dedicated staging Add Budget opp; net-zero).
A12: OD_11 | B12: Verify user is able to increase the visits for existing workers | C12: 1. Login to CCC web UI 2. Navigate to Opp dashboard >> Hamburger option 3. Click on Add budget 4. Under existing workers tab, select the workers you want to increase the visits 5. Enter the no.of visits and select "increase" option 6. Click save | D12: The user’s total max visits should increase proportionally across all payment units (i.e., change × number of payment units). | G12: AUTOMATION: Automated - PR #38, test_opd_budget_mutations.py::test_opd_11_increase_visits_proportional (delta = N x payment units; net-zero).
A13: OD_12 | B13: Verify user is able to increase the visits for existing workers | C13: 1. Login to CCC web UI 2. Navigate to Opp dashboard >> Hamburger option 3. Click on Add budget 4. Under existing workers tab, select the workers you want to decrease the visits 5. Enter the no.of visits and select to "decerase" option 6. Click save | D13: The user’s total max visits should decrease proportionally across all payment units (i.e., change × number of payment units). | G13: AUTOMATION: Automated - PR #38, test_opd_budget_mutations.py::test_opd_12_decrease_visits_proportional (net-zero increase-then-decrease).
A14: OD_13 | B14: Verify error pop up is displayed by entering negative numbers in the visits field | C14: 1. Login to CCC web UI 2. Navigate to Opp dashboard >> Hamburger option 3. Click on Add bduget option 4. Enter the negative number in visits field 5. Click Save | D14: - The following error message is displayed "Value must be greater than or equal to 1" | G14: AUTOMATION: Automated - PR #38, test_opd_budget.py::test_opd_13_negative_visits_validation (number_of_visits min=1 via browser ValidityState).
A15: OD_14 | B15: Confirm user is not able decrease the completed visits | C15: 1. Login to CCC web UI 2. Navigate to Opp dashboard >> Hamburger menu >> Add budget 3. Enter the number of visits including the completed count >> Click save | D15: - User should be not able to decrease the completed visits and following error message is displayed: "Cannot decrease the number of visits for user(s). The visit count cannot be reduced below the number of already completed visits or zero" | G15: AUTOMATION: Automated - PR #38, test_opd_budget_mutations.py::test_opd_14 (decrease below completed/zero rejected with 'Cannot decrease...' error; no change). Exercised via a below-zero decrease (same validation/message); the exact below-COMPLETED path additionally needs a worker with completed visits.
A16: OD_15 | B16: Verify that changes to delivery visits are correctly reflected on the Connect Workers page and on mobile. | C16: 1. Login to CCC web Ui 2. Hamuburger option >> Add budget 3. Add visits and budget to the worker >> save | D16: - Applied visit changes are updated on the connect workers page | G16: AUTOMATION: Web reflection automated (Connect Workers/Deliver max-visit denominators) - PR #38, test_opd_budget_mutations.py::test_opd_15_change_reflected_on_connect_workers. MOBILE REFLECTION NOT AUTOMATED (updated visit count on the device) - out of web scope; needs the same Maestro mobile hybrid follow-up as OD_8.
