Workbook

Sheet Read Me
A1: Read Me — Tab Guide & Legend
A2: Connect QA Gap Analysis · Mobile App Regression stream
A4: TWO OUTPUTS OF THIS EXERCISE
A5: Output 1: MTP completeness | B5: Everything the product does that was NOT documented in this test plan. ALL functional gaps get added to the plan, whether or not engineering already tests them.
A6: Output 2: QA automation backlog | B6: The subset QA still needs to automate — the ones engineering does NOT already cover. Filter the Gap Analysis Action column for "Automate".
A8: TAB GUIDE (4 analysis tabs)
A9: Read Me | B9: This tab. The key to the workbook.
A10: Dashboard | B10: One-screen live dashboard: the two outputs (add-to-MTP / automate), dev + reconcile counts, AND the Coverage Tracker — per-surface automation % of existing MTP cases. Read this first.
A11: Gap Analysis (MAIN OUTPUT) | B11: Every coverage gap found — behaviour in the code with NO case in the test plan. Each row has its Bucket, Eng Coverage, and Action. Reviewers work here.
A12: Automation (existing MTP) | B12: The existing master test cases and their automation status: Green = already automated, Yellow = automatable-not-built, Red = manual-only. (This is the pass-1 baseline; the Dashboard Coverage Tracker rolls it up.)
A14: ORIGINAL TABS (not from this exercise)
A15: Test Tracker / Test Tracker Horizontal | B15: Pre-existing manual-execution trackers (run pass/fail). Left untouched.
A16: Surface tabs (Login, Opportunity creation, Visit verification, ...) | B16: The existing master test plan — documented cases by product area. The "before" picture the gap analysis was measured against.
A18: GAP ANALYSIS — 3 row types (by Gap ID prefix)
A19: Functional gap | B19: Behaviour in code with no MTP case. Core finding. IDs: GAP-SRC-*, GAP-BE-*, GAP-FE-*.
A20: Unit-test-coverage gap (dev) | B20: Where ENG code lacks a unit test. For dev teams. IDs: GAP-UTC-*.
A21: Cross-cutting | B21: Hygiene / MTP-vs-code discrepancy / automation note. IDs: GAP-MISC-*, GAP-MMISC-*.
A23: BUCKET column | B23: 🟢 Already automated · 🟡 Automatable-not-done (backlog) · 🔴 Manual only (real SMS/OTP/push/camera/device)
A24: ENG COVERAGE column | B24: Eng-covered (logic) = eng already tests it, QA e2e only if critical · QA-owned = eng cannot cover · Partial = confirm w/ eng · Eng GAP = eng missing a unit test · N/A
A25: ACTION column | B25: Add to MTP only (eng-covered) · Add to MTP + Automate (QA-owned) · Add to MTP + Automate (confirm w/ eng) · Dev: add unit test · Reconcile (plan/code)

Sheet Dashboard
A1: Dashboard — outputs & coverage (live)
A3: OUTPUTS (from Gap Analysis)
A4: Output 1: functional gaps to ADD to MTP | B4: =COUNTIF('Gap Analysis'!$L:$L,"Add to MTP*")
A5: ...of which eng-covered (add to MTP only, do NOT automate) | B5: =COUNTIF('Gap Analysis'!$L:$L,"Add to MTP only*")
A6: Output 2: functional gaps to AUTOMATE (QA backlog) | B6: =COUNTIF('Gap Analysis'!$L:$L,"*Automate*")
A7: ...of which QA-owned (eng cannot cover) | B7: =COUNTIF('Gap Analysis'!$L:$L,"*QA-owned*")
A8: Dev: unit-test-coverage gaps | B8: =COUNTIF('Gap Analysis'!$L:$L,"Dev:*")
A9: Cross-cutting: reconcile plan/code | B9: =COUNTIF('Gap Analysis'!$L:$L,"Reconcile*")
A10: Total Gap Analysis rows | B10: =COUNTA('Gap Analysis'!$A$2:$A$1000)
A12: COVERAGE TRACKER — automation of existing MTP cases
A13: Surface | B13: Automated (built) | C13: Automatable (not built) | D13: Manual only | E13: Total | F13: % Automated | G13: Note
A14: Personal ID Tests | B14: =COUNTIFS('Automation (existing MTP)'!$B:$B,$A14,'Automation (existing MTP)'!$D:$D,"🟢*") | C14: =COUNTIFS('Automation (existing MTP)'!$B:$B,$A14,'Automation (existing MTP)'!$D:$D,"🟡*") | D14: =COUNTIFS('Automation (existing MTP)'!$B:$B,$A14,'Automation (existing MTP)'!$D:$D,"🔴*") | E14: =B14+C14+D14 | F14: =IF(E14>0,B14/E14,0)
A15: Integration Tests (Connect) | B15: =COUNTIFS('Automation (existing MTP)'!$B:$B,$A15,'Automation (existing MTP)'!$D:$D,"🟢*") | C15: =COUNTIFS('Automation (existing MTP)'!$B:$B,$A15,'Automation (existing MTP)'!$D:$D,"🟡*") | D15: =COUNTIFS('Automation (existing MTP)'!$B:$B,$A15,'Automation (existing MTP)'!$D:$D,"🔴*") | E15: =B15+C15+D15 | F15: =IF(E15>0,B15/E15,0)
A16: Connect Landing Page | B16: =COUNTIFS('Automation (existing MTP)'!$B:$B,$A16,'Automation (existing MTP)'!$D:$D,"🟢*") | C16: =COUNTIFS('Automation (existing MTP)'!$B:$B,$A16,'Automation (existing MTP)'!$D:$D,"🟡*") | D16: =COUNTIFS('Automation (existing MTP)'!$B:$B,$A16,'Automation (existing MTP)'!$D:$D,"🔴*") | E16: =B16+C16+D16 | F16: =IF(E16>0,B16/E16,0)
A17: Connect messaging | B17: =COUNTIFS('Automation (existing MTP)'!$B:$B,$A17,'Automation (existing MTP)'!$D:$D,"🟢*") | C17: =COUNTIFS('Automation (existing MTP)'!$B:$B,$A17,'Automation (existing MTP)'!$D:$D,"🟡*") | D17: =COUNTIFS('Automation (existing MTP)'!$B:$B,$A17,'Automation (existing MTP)'!$D:$D,"🔴*") | E17: =B17+C17+D17 | F17: =IF(E17>0,B17/E17,0)
A18: Connect Notifications | B18: =COUNTIFS('Automation (existing MTP)'!$B:$B,$A18,'Automation (existing MTP)'!$D:$D,"🟢*") | C18: =COUNTIFS('Automation (existing MTP)'!$B:$B,$A18,'Automation (existing MTP)'!$D:$D,"🟡*") | D18: =COUNTIFS('Automation (existing MTP)'!$B:$B,$A18,'Automation (existing MTP)'!$D:$D,"🔴*") | E18: =B18+C18+D18 | F18: =IF(E18>0,B18/E18,0)
A19: Connect worker History | B19: =COUNTIFS('Automation (existing MTP)'!$B:$B,$A19,'Automation (existing MTP)'!$D:$D,"🟢*") | C19: =COUNTIFS('Automation (existing MTP)'!$B:$B,$A19,'Automation (existing MTP)'!$D:$D,"🟡*") | D19: =COUNTIFS('Automation (existing MTP)'!$B:$B,$A19,'Automation (existing MTP)'!$D:$D,"🔴*") | E19: =B19+C19+D19 | F19: =IF(E19>0,B19/E19,0)
A20: Case List map | B20: =COUNTIFS('Automation (existing MTP)'!$B:$B,$A20,'Automation (existing MTP)'!$D:$D,"🟢*") | C20: =COUNTIFS('Automation (existing MTP)'!$B:$B,$A20,'Automation (existing MTP)'!$D:$D,"🟡*") | D20: =COUNTIFS('Automation (existing MTP)'!$B:$B,$A20,'Automation (existing MTP)'!$D:$D,"🔴*") | E20: =B20+C20+D20 | F20: =IF(E20>0,B20/E20,0)
A21: TOTAL | B21: =SUM(B14:B20) | C21: =SUM(C14:C20) | D21: =SUM(D14:D20) | E21: =SUM(E14:E20) | F21: =IF(E21>0,B21/E21,0)

Sheet Gap Analysis
A1: Gap ID | B1: Surface | C1: Description | D1: Bucket | E1: Rationale/Source | F1: Priority | G1: Status | H1: Assignee | I1: Reviewer's Notes | J1: Source | K1: Eng Coverage | L1: Action
A2: GAP-MMISC-01 | B2: Cross-cutting | C2: Duplicate TC_ ID namespace: 'Personal ID Tests' and 'Integration Tests (Connect)' both number TC_01, TC_02... - impossible to reference a case unambiguously | D2: 🟡 Automatable - not yet done | E2: MTP hygiene: namespace collision across two tabs | F2: High | G2: New | J2: Pass 1 (mobile): MTP vs test suite | K2: N/A (hygiene/discrepancy/automation note) | L2: Reconcile (plan/code)
A3: GAP-MMISC-02 | B3: Cross-cutting | C3: Mobile suite allure tags use an older scheme (PID_x/CONNECT_x/Notification_x/Messaging_x) that no longer matches current MTP IDs (TC_/OLP_/Notifications_) - covered-case mapping is best-guess until reconciled | D3: 🟡 Automatable - not yet done | E3: Suite/MTP ID drift discovered in mobile pass 1 | F3: High | G3: New | J3: Pass 1 (mobile): MTP vs test suite | K3: N/A (hygiene/discrepancy/automation note) | L3: Reconcile (plan/code)
A4: GAP-MMISC-03 | B4: Cross-cutting | C4: test_tc_03 wraps push-notification assertions in bare try/except (flag=True/False) - the invite-notification check can silently pass | D4: 🟡 Automatable - not yet done | E4: Suite quality: assertions swallowed; fix in automation repo | F4: High | G4: New | J4: Pass 1 (mobile): MTP vs test suite | K4: N/A (hygiene/discrepancy/automation note) | L4: Reconcile (plan/code)
A5: GAP-MMISC-04 | B5: Cross-cutting | C5: Connect Landing Page tab header row has no 'Test Case ID' label in col A and starts mid-table - confirm no cases dropped in parsing | D5: 🟡 Automatable - not yet done | E5: MTP hygiene: malformed header row | F5: Medium | G5: New | J5: Pass 1 (mobile): MTP vs test suite | K5: N/A (hygiene/discrepancy/automation note) | L5: Reconcile (plan/code)
A6: GAP-MMISC-05 | B6: Cross-cutting | C6: Connect messaging tab is duplicated between web MTP and mobile MTP with overlapping IDs - decide the single owner | D6: 🟡 Automatable - not yet done | E6: Cross-MTP duplication (web vs mobile messaging) | F6: Medium | G6: New | J6: Pass 1 (mobile): MTP vs test suite | K6: N/A (hygiene/discrepancy/automation note) | L6: Reconcile (plan/code)
A7: GAP-MMISC-06 | B7: Cross-cutting | C7: test_tc_06 duplicates the commented-out test_06 body from test_tc_03 - dead code in suite | D7: 🟡 Automatable - not yet done | E7: Suite hygiene: dead/duplicated code | F7: Low | G7: New | J7: Pass 1 (mobile): MTP vs test suite | K7: N/A (hygiene/discrepancy/automation note) | L7: Reconcile (plan/code)
A8: GAP-SRC-M-01 | B8: PersonalID - Email | C8: Email OTP collection: app offers to collect + verify an email after login (EmailOfferHelper), with sendEmailOtp/verifyEmailOtp endpoints | D8: 🔴 Manual only | E8: MISSING from MTP - entire email-OTP path absent. Real email round-trip. Src: EmailOfferHelper.kt, ApiPersonalId.sendEmailOtp/verifyEmailOtp | F8: High | G8: New | J8: Pass 4 (mobile): commcare-android Connect source | K8: QA-owned (real device/external; eng cannot unit-test) | L8: Add to MTP + Automate (QA-owned)
A9: GAP-SRC-M-02 | B9: PersonalID - Email | C9: Email offer cadence: offered at most twice, second offer only after 30 days, skipped if email already set or toggle off | D9: 🟡 Automatable - not yet done | E9: MISSING from MTP. Logic-level, unit-testable (EmailOfferHelperTest exists). Src: EmailOfferHelper.shouldOfferEmail | F9: Medium | G9: New | J9: Pass 4 (mobile): commcare-android Connect source | K9: Eng-covered (logic) - QA e2e only if critical journey | L9: Add to MTP only (eng-covered)
A10: GAP-SRC-M-03 | B10: PersonalID - Signup | C10: Device integrity / Play Integrity attestation during signup (reportIntegrity, startConfiguration; INTEGRITY_ERROR handling) | D10: 🔴 Manual only | E10: MISSING from MTP. Google Play Integrity infra. Src: ApiPersonalId.reportIntegrity/startConfiguration, PersonalIdApiHandler | F10: High | G10: New | J10: Pass 4 (mobile): commcare-android Connect source | K10: QA-owned (real device/external; eng cannot unit-test) | L10: Add to MTP + Automate (QA-owned)
A11: GAP-SRC-M-04 | B11: PersonalID - Signup | C11: Firebase ID token validation with phone match; PHONE_MISMATCH error when the token phone differs | D11: 🔴 Manual only | E11: MISSING from MTP. Firebase infra. Src: ApiPersonalId.validateFirebaseIdToken, PersonalIdApiHandler PHONE_MISMATCH | F11: High | G11: New | J11: Pass 4 (mobile): commcare-android Connect source | K11: QA-owned (real device/external; eng cannot unit-test) | L11: Add to MTP + Automate (QA-owned)
A12: GAP-SRC-M-05 | B12: PersonalID - Signup | C12: Duplicate-account block: ACTIVE_USER_EXISTS error when signing up with a phone already tied to an active account | D12: 🟡 Automatable - not yet done | E12: MISSING from MTP (TC_18 covers fuzzy NAME dup, not phone). Src: PersonalIdApiHandler ACTIVE_USER_EXISTS | F12: High | G12: New | J12: Pass 4 (mobile): commcare-android Connect source | K12: Eng-covered (logic) - QA e2e only if critical journey | L12: Add to MTP only (eng-covered)
A13: GAP-SRC-M-06 | B13: PersonalID - Signup | C13: Unsupported-country / phone-not-validated block (UNSUPPORTED_COUNTRY, PHONE_NOT_VALIDATED -> FORBIDDEN) | D13: 🟡 Automatable - not yet done | E13: MISSING from MTP. Src: PersonalIdApiHandler UNSUPPORTED_COUNTRY/PHONE_NOT_VALIDATED | F13: Medium | G13: New | J13: Pass 4 (mobile): commcare-android Connect source | K13: Eng-covered (logic) - QA e2e only if critical journey | L13: Add to MTP only (eng-covered)
... A106: GAP-UTC-M-06 | B106: Cross-cutting | C106: connect-id backend is well unit-tested (users/messaging/payments have test suites); the only thin spot is the connectid project app (connectid/views.py + project config) which has no tests | D106: 🟡 Automatable - not yet done | E106: Unit-test coverage note (connect-id) - completes mobile UTC symmetry. Src: connectid/views.py | F106: Low | G106: New | J106: connect-id: unit-test-coverage note | K106: Eng GAP (no unit test) - dev deliverable | L106: Dev: add unit test

Sheet Automation (existing MTP)
A1: Case / Gap ID | B1: Surface | C1: Description | D1: Status | E1: Detail | F1: Source
A2: TC_01 | B2: Personal ID Tests | C2: Confirm an existing user is able to sign in and is able to continue to work | D2: 🟢 Already automated | E2: test_tc_01 (existing demo-user sign-in) | F2: Confirmed automated (pass 1)
A3: TC_03 | B3: Personal ID Tests | C3: Verify user can logout of Personal ID and re-authenitcate themselves | D3: 🟢 Already automated | E3: test_tc_01 (forget PID / re-auth) | F3: Confirmed automated (pass 1)
A4: TC_28 | B4: Personal ID Tests | C4: Verify user is able to sign out, by clicking "Forget PersonalID user" | D4: 🟢 Already automated | E4: test_tc_01 (forget PersonalID sign out) | F4: Confirmed automated (pass 1)
A5: TC_31 | B5: Personal ID Tests | C5: Verify user is unable to recover the account, if they enter a wrong backup code | D5: 🟢 Already automated | E5: test_tc_01 (wrong backup code error) | F5: Confirmed automated (pass 1)
A6: TC_32 | B6: Personal ID Tests | C6: Verify user account is locked when they enter the backup code wrong more than 3 times | D6: 🟢 Already automated | E6: test_tc_02 (account locked popup) | F6: Confirmed automated (pass 1)
A7: TC_01 | B7: Integration Tests (Connect) | C7: Confirm after signing up with a Personal ID, user sees all the connect options in the side menu | D7: 🟢 Already automated | E7: test_tc_01 (connect side-menu options) | F7: Confirmed automated (pass 1)
A8: TC_08 | B8: Integration Tests (Connect) | C8: Verify on clicking the opportunities option from the side drawer takes you to the opportunity list page | D8: 🟢 Already automated | E8: test_tc_03 (opportunities option -> list) | F8: Confirmed automated (pass 1)
A9: TC_10 | B9: Integration Tests (Connect) | C9: Verify on clicking the messaging option, user is taken channels list page | D9: 🟢 Already automated | E9: test_tc_07 (messaging -> channels list) | F9: Confirmed automated (pass 1)
A10: TC_17 | B10: Integration Tests (Connect) | C10: Verify mobile users sess all the opportunities that they are invited to on the opportunity list page | D10: 🟢 Already automated | E10: test_tc_03 (opportunity list shown) | F10: Confirmed automated (pass 1)
A11: TC_20 | B11: Integration Tests (Connect) | C11: Verify on selecting the view opportunity button, user sees the description and all the opportunity details | D11: 🟢 Already automated | E11: test_tc_03 (view opportunity details/job card) | F11: Confirmed automated (pass 1)
A12: TC_21 | B12: Integration Tests (Connect) | C12: Ensure that after downloading the learn app, the opportunity status gets updated on the mobile | D12: 🟢 Already automated | E12: test_tc_04 (learn app in-progress status) | F12: Confirmed automated (pass 1)
... A167: GAP-MAP-11 | B167: Case List map | C167: [Map_11] Verify user can toggle polygons and points ON/OFF | D167: 🔴 Manual only | E167: Map canvas rendering/interaction - no stable selectors (reviewer to confirm) | F167: Pass 1 (mobile): MTP vs test suite

Sheet  Test Tracker
B1: CCC: Mobile Regression [Master] | F1: Keys
F2: Pass | H2: Passed steps of Test Case
F3: Fail | H3: Failed steps of Test Case
F4: N/A | H4: Not applicable to your testing
F5: Blocking | H5: Failed and is a critical feature or cannot proceed with testing
A6: Name of Tester | B6: Start Date | C6: End Date | F6: Unanswered | H6: Unanswered/ blank test cases
A9: Tab | B9: Execution Status | C9: Duration (In Hours) | D9: Comments (if any) | F9: Case Results (if none, displays as 0) | K9: Total | M9: Ticket Summaries (if none, displays as #N/A)
A10: =sheetName(2) | F10: =countif(INDIRECT("'"&A10&"'!"&"E2:E100"), "Pass") | G10: =countif(INDIRECT("'"&A10&"'!"&"E2:E100"), "Fail") | H10: =countif(INDIRECT("'"&A10&"'!"&"E2:E100"), "N/A") | I10: =countif(INDIRECT("'"&A10&"'!"&"E2:E100"), "Blocking") | J10: =countif(INDIRECT("'"&A10&"'!"&"E2:E100"), "") | K10: =sum(F10:J10) | M10: =IFERROR(__xludf.DUMMYFUNCTION(" TRANSPOSE(UNIQUE( FILTER( INDIRECT(""'""&$A$10&""'!""&""F2:F100"") , NOT(ISBLANK(INDIRECT(""'""&$A$10&""'!""&""F2:F100""))) ) ))"),"#N/A")
A11: =sheetName(3) | F11: =countif(INDIRECT("'"&A11&"'!"&"E2:E100"), "Pass") | G11: =countif(INDIRECT("'"&A11&"'!"&"E2:E100"), "Fail") | H11: =countif(INDIRECT("'"&A11&"'!"&"E2:E100"), "N/A") | I11: =countif(INDIRECT("'"&A11&"'!"&"E2:E100"), "Blocking") | J11: =countif(INDIRECT("'"&A11&"'!"&"E2:E100"), "") | K11: =sum(F11:J11) | M11: =IFERROR(__xludf.DUMMYFUNCTION(" TRANSPOSE(UNIQUE( FILTER( INDIRECT(""'""&$A$10&""'!""&""F2:F100"") , NOT(ISBLANK(INDIRECT(""'""&$A$10&""'!""&""F2:F100""))) ) ))"),"#N/A")
A12: =sheetName(4) | F12: =countif(INDIRECT("'"&A12&"'!"&"E2:E100"), "Pass") | G12: =countif(INDIRECT("'"&A12&"'!"&"E2:E100"), "Fail") | H12: =countif(INDIRECT("'"&A12&"'!"&"E2:E100"), "N/A") | I12: =countif(INDIRECT("'"&A12&"'!"&"E2:E100"), "Blocking") | J12: =countif(INDIRECT("'"&A12&"'!"&"E2:E100"), "") | K12: =sum(F12:J12)
A13: =sheetName(5) | F13: =countif(INDIRECT("'"&A13&"'!"&"E2:E100"), "Pass") | G13: =countif(INDIRECT("'"&A13&"'!"&"E2:E100"), "Fail") | H13: =countif(INDIRECT("'"&A13&"'!"&"E2:E100"), "N/A") | I13: =countif(INDIRECT("'"&A13&"'!"&"E2:E100"), "Blocking") | J13: =countif(INDIRECT("'"&A13&"'!"&"E2:E100"), "") | K13: =sum(F13:J13)
A14: =sheetName(6) | F14: =countif(INDIRECT("'"&A14&"'!"&"E2:E100"), "Pass") | G14: =countif(INDIRECT("'"&A14&"'!"&"E2:E100"), "Fail") | H14: =countif(INDIRECT("'"&A14&"'!"&"E2:E100"), "N/A") | I14: =countif(INDIRECT("'"&A14&"'!"&"E2:E100"), "Blocking") | J14: =countif(INDIRECT("'"&A14&"'!"&"E2:E100"), "") | K14: =sum(F14:J14)
A15: =sheetName(7) | F15: =countif(INDIRECT("'"&A15&"'!"&"E2:E100"), "Pass") | G15: =countif(INDIRECT("'"&A15&"'!"&"E2:E100"), "Fail") | H15: =countif(INDIRECT("'"&A15&"'!"&"E2:E100"), "N/A") | I15: =countif(INDIRECT("'"&A15&"'!"&"E2:E100"), "Blocking") | J15: =countif(INDIRECT("'"&A15&"'!"&"E2:E100"), "") | K15: =sum(F15:J15)
A16: =sheetName(8) | F16: =countif(INDIRECT("'"&A16&"'!"&"E2:E100"), "Pass") | G16: =countif(INDIRECT("'"&A16&"'!"&"E2:E100"), "Fail") | H16: =countif(INDIRECT("'"&A16&"'!"&"E2:E100"), "N/A") | I16: =countif(INDIRECT("'"&A16&"'!"&"E2:E100"), "Blocking") | J16: =countif(INDIRECT("'"&A16&"'!"&"E2:E100"), "") | K16: =sum(F16:J16)

Sheet Personal ID Tests
A1: Test Case ID | B1: Description | C1: Steps | D1: Outcome | E1: Status (Pass/Fail) | F1: Ticket/ Bug | G1: Comments
A2: TC_01 | B2: Confirm an existing user is able to sign in and is able to continue to work | C2: 1. Install CCC app 2. Expand left hand menu 3. Click on sign up/ register for personal ID 4. Sign up with personal ID 5. Verify all the opportunities progress is able to resume | D2: Exisiting user should be able to sign in and continue to workl
A3: TC_02 | B3: Verify when user updates to the latest beta app, the user remains signed in | C3: 1. Sign up for personal ID 2. Update the app to latest version | D3: - Already signed in user should remain signed in on updating to the latest version - The user shouldn't lose any information or progress for any of the opportunity
A4: TC_03 | B4: Verify user can logout of Personal ID and re-authenitcate themselves | C4: 1. Sign up for personal ID 2. Submit few delivery forms for an opportunity 3. Click on 3 dots menu >> forget personal ID 4. Again sign up for personal ID | D4: User should be able to resume work after sign-ing in again
A5: TC_04 | B5: Verify user sees a new Hamburger menu on the left side top corner | C5: 1. Install CCC app 2. Expand left hand menu 3. Click on sign up/ register for personal ID 4. Sign up with personal ID | D5: User should be able to see the hamburger option - Upon clicking it hamburger option, new side navigation drawer should get open - Should see a "sign up/register for personalID", "About" options
A6: TC_05 | B6: Verify on clicking the "Sign up Personal ID" option, user is redirected to the Start Page | C6: 1. Install CCC app 2. Expand left hand menu 3. Click on sign up for personal ID | D6: User should be taken to the Start page and see the following changes on the page: - Name of the page should be "Get Started with PersonalID" - User should only see one field to enter the phone number - The field name should be "Enter your Phone Number" - User should see a continue button as well - User should also see a T&Cs checkbox
A7: TC_06 | B7: Verify validations for the phone number field | C7: Continue from above TC - enter mobile number | D7: - User should see the country code auto-filled when they land on the start page - User should be able to enter any digits into the field - User shold not be able to continue without entering a valid mobile number - The button should remain disabled if the number of digits entered for the phone number is less than the required digits for that country’s format (e.g., for an Indian number, the user must enter 10 digits).
A8: TC_07 | B8: Confirm on clicking the continue button, user is taken to the Android Device Authentication page | C8: Continue from above TC - enter mobile number and continue | D8: - User should be asked to verify themselves by using PIN/Pattern or biometrics that they have configured for their android device
A9: TC_08 | B9: Verify that user is taken to device settings, to configure authentication when there's no device authentication configured | C9: Prerequisite: Mobile device shouldn't be have any lock/finger print configurations 1. Click on Sign up for personal ID 2. Enter mobile number and click continue 3. Click on configure fingerprint 4. User should be taken to device settings to configure fingerprint | D9: - User should be taken to the settings to configure fingerprints on the device - User should see the option "Configure Fingerprint" on the screen when there's no biometrics configured on the device
A10: TC_09 | B10: Verify on authenticating the android device successfully, user is taken to the OTP page | C10: Continue to above TC - Click on agree & continue - Scan fingerprint/ enter lock pin or pattern - user lands on the otp page | D10: - User should be redirected to the OTP screen once they have successfully authenticated the android device
A11: TC_10 | B11: Confirm when user lands on the OTP page, they receive an OTP on the mobile number they entered on the Start page | D11: - User should recieve an OTP on the mobile number they entered when they land on the OTP page - Verify and Resend button should remain greyed out
A12: TC_11 | B12: Confirm user is able to resen code after 120 seconds only | C12: 1.Click on sign up for personal ID 2. Enter mobile number 3. Authenticate with app lock/finger print 4. Otp generates, wait 120 seconds and resend code button is enabled 5. Click on resend button | D12: - User should only be able to click on the Resend button after the 120 secs have passed - They should receive the same OTP again when they click on the resend code button - The button should get disabled again after user have pressed it
A13: TC_12 | B13: Confirm that the verify button gets enabled when user enter the OTP code | C13: Continue from above TC - Enter the generated otp in the fields - Verify button is enabled | D13: - Verify button should get enabled when user enters a code in the OTP field - Button shouold get enabled even if the OTP entered is wrong
A14: TC_13 | B14: Verify user cannot verify the phone by entering the wrong OTP | C14: Continue from above TC - Enter the wrong otp >> click on verify button | D14: - User should see an error message if they enter the wrong OTP and click on verify button
A15: TC_14 | B15: Confirm that user is able to enter and delete any digit in the OTP fields | D15: - User should be able to enter any digits in the OTP fields without any issue - User should also be able to delete any digit in the OTP fields and the cursor should move back to the previous field
A16: TC_15 | B16: Verify on successfully verifying the OTP, user is taken to the Name page | C16: Cont from above TC - Enter correct otp >> click on verify button | D16: - User should be redirected to the Name page on entering the correct OTP
A17: TC_16 | B17: Confirm user can change the phone number by clicking the 'change' option | C17: 1.Click on sign up for personal ID 2. Enter mobile number 3. Click on change option on verification code page | D17: - User should be redirected back to the Start page if they click on the change option - User should be able to edit the phone number and restart the sign up process again
A18: TC_17 | B18: Confirm user sees the page title and name field on the Name page | C18: 1. Click on sign up for personal ID 2. Enter mobile number 3. Agree and continue with fingerprint 4. Enter otp and verify 5. User lands on the name page | D18: - User should see the subtitle heading on the page "Please enter your name as it appears on your government-issued identification" - User should also see a Name field and a continue button on the screen
A19: TC_18 | B19: Confirm users name is verified agains the DB for potential duplicate account | C19: cont from above TC - Enter name and click continue | D19: - After the user selects “Continue” the system will be validating this name against a fuzzy match of possible names in the DB to suggest possible duplicates. - From here the flow will branch depending upon if this is a new or returning user
A20: TC_19 | B20: Confirm user lands on the "Backup Code" screen after entering the name | C20: cont from above TC - Click continue on name page - User land son the back up code screen | D20: - User should land on the "Backup Code" page/screen - Here, Dimagi logo should've been updated by CommCare logo - User should see two fields to setup backup code and continue button
A21: TC_20 | B21: Verify user can setup a backup code and conitnue forward | C21: cont from above TC - Enter the back up code field - Enter the same code in confirm field - Click on continue | D21: - User should be able to setup a new bacup code by entering the same code in both the fields i) Code ii) Confirm Code - User should be be navigated to the 'Photo' page on clicking continue
A22: TC_21 | B22: Ensure user can only continue if they enter the same code in the two input boxes | D22: - User should see an error message, when the code in the two input fields do not match - User should not be able to continue to next page
A23: TC_22 | B23: Verify user can see the code they have entered by clicking the eye icon | D23: - On clicking the eye icon on the two fields, the backup code should get revealed to the user - They should be able to undo it by clicking the icon again
A24: TC_23 | B24: Confirm user is taken to the "Take Photo" page after they have configured the backup code | C24: 1. Configure the back up code 2. Click on continue 3. User lands on capture photo page | D24: - User should see the commcare logo on the screen instead of Dimagi logo - User should see 'Welcome xyz" and "Please take a photo of yourself to complete your account setup" with a profile icon on the page - User should also see two buttons Take Photo (enabled) and Save Photo (disabled)
A25: TC_24 | B25: Confirm that user can take a photo by clicking take photo option | C25: continue from above TC - Click on the take photo option | D25: - Front camera should open when, user clicks on "Take Photo" option - User should be able to click a selfie when the camera opens. (It should auto capture as there is no click button) - User should see the clicked picture on the screen and 'Save button' should get enabled
A26: TC_25 | B26: Confrm user can replace the photo they saved | C26: cont from above TC: - Click on take photo option to replace photo | D26: - User should be able to replace the photo by taking a new photo - The picutre should get updated by the new one on the 'Capture Photo' screen
A27: TC_26 | B27: Confirm user can save the picture and the account is created | C27: cont from above TC - Click on save photo button | D27: - On cicking the save photo option, the account should get created - User should see a pop-up message, that account created successfully - User should be taken to the either the CommCare HQ mobile app or Connect homescreen on clicking OK on the pop-up
A28: TC_27 | B28: Verify user sees a pop-up on successful account creation | C28: cont from above TC - Account created successfully message is appeared | D28: - User should see 'Account Created' pop-up on the screen on saving the photo with the text "Your Personal ID account has been successfully created and is now ready for you to use!" - User should be redirected to CommCare HQ mobile app and do not see "Go to Connect Menu" option
A29: TC_28 | B29: Verify user is able to sign out, by clicking "Forget PersonalID user" | C29: cont from above TC - Click on 3 dot menu - Click on forget personal ID option | D29: - User should be able to sign out of the personal id by clicking the option - On again clicking the three dot option, use should see "Sign up for PersonalID option
A30: TC_29 | B30: Confirm when user enters an existing phone number, on verifying the number they are taken to the "Enter Backup Code" screen | C30: 1. Click on sign up for personal ID 2. Enter personal ID number 3. Verify with fingerprint 4. Verify with otp 5. Enter name and click continue 6. Enters on backup code screen | D30: - When recovering an account, user should be taken to the "Enter Backup Code" screen - On entering the correct backup code, user should be able to revocer the account - They should see a success message that the account is recovered
A31: TC_30 | B31: Verify user see there name and photo associated with the account on the screen | D31: - User should see there picture on the screen and following text "Welcom back username" - They should also see a field to enter the Personal ID Backup Code on the screen | G31: "This is not me" option is deprecated
A32: TC_31 | B32: Verify user is unable to recover the account, if they enter a wrong backup code | C32: - Enter wrong back up code | D32: - User shouldn't be able to recover there account on entering the wrong backup code - User should see an error pop-up message, that says "Wrong Backup code and informing user that they have only 2 more incorrect attempts left
A33: TC_32 | B33: Verify user account is locked when they enter the backup code wrong more than 3 times | C33: - Enter wrong back up code more than 3 times | D33: - On entering the incorrect backup code more that 3 times, user account will be locked
A34: TC_35 | B34: Confirm on devices that don't support fingerprint, user is uanble to sign up for Personal ID | C34: Prerequisite: Mobile device shouldn't support fingerprint option 1. Click on sign up for personal ID 2. Enter mobile number >> click on continue | D34: - User should see a Process Failed pop-up with the following message "Your device isn't eligible to sign up for PersonalID at this time due to non availability of biometrci security feature. Please try again on a different device." - On pressing 'OK' user should be taken back to the Start page.
A35: TC_36 | B35: Verify on logging in on a CC app, user sees a 'Link to Personal ID' pop up | C35: 1. Sign up for personal ID 2. Install CC app using barcode 3. Login to the CC app | D35: - User should see a pop-up to link the MW with the Personal ID, "Do you want to link the login to your PersonalID account? You will not need to type your password in the future." - User should see two options i) Yes ii) No
A36: TC_38 | B36: Verify on selecting 'No' user is able to log into the CC app | C36: cont from above TC - Select No for the "Do you want to link the login to your PersonalID account? You will not need to type your password in the future." pop up | D36: - On selecting 'NO', user is able to login into the CC app - User is able to submit forms without issue - The pop-up does not appears again when user logs out and login again on the app
A37: TC_39 | B37: Confirm the MW is now linked with the PersonalID when user clicks on 'Yes' on the pop-up | C37: - Select Yes for the "Do you want to link the login to your PersonalID account? You will not need to type your password in the future." pop up | D37: - MW should be linked to the PersonalID account - User should not have to enter password again to login
A38: TC_40 | B38: Verify user can also login on the CC app by entering password | C38: cont to above TC - Login to app using password | D38: - User should be able to login by entering the password - User should also see a Unlink PersonalID pop up "I see you logged in with your password although PersonalID was configured for auto-login. Would you like to sever this login from PersonalID?" - User should see two options i) Yes ii) No
A39: TC_41 | B39: Verify if user selects 'Yes' on the Unlink PersonalID pop-up, MW unlinks | C39: cont to above TC - Login to app using password - Click 'yes' to unlink personal ID | D39: - MW should be unlinked to the Personal ID and user can no longer log into the CC apps using PersonalID - User should only be able to login using password
A40: TC_42 | B40: Confirm on selecting 'No'on the unlinl PersonalID option, MW remains linked to the PersonalID | C40: cont to above TC - Login to app using password - Click 'NO' to not unlink personal ID | D40: - User should not be unlinked and should be able to login using the PersonalID
...

Sheet Integration Tests (Connect)
A1: Test Case ID | B1: Description | C1: Steps | D1: Expected Outcome | E1: Status (Pass/Fail) | F1: Ticket/ Bug ID | G1: Comments
A2: TC_01 | B2: Confirm after signing up with a Personal ID, user sees all the connect options in the side menu | C2: 1. Install commcare mobile app 2. Click on the hamburger option and sign up for personal ID uisng existing number 3. After login with personal ID, expand the side navigation drawer by cliking on the hamburger option 4. Verify all connect options are displayed on the side navigation drawer | D2: User should see the following options in the side menu, after signing up for Personal ID - Oppoortunities - CommCare Apps - Messaging - Work History - Payments | G2: Payments pages aren't ready and will be only be available in the later release
A3: TC_02 | B3: Verify if there are no apps installed on the device, the CommCare apps option is greyed out | C3: 1. Install commcare mobile app 2. Click on the hamburger option and sign up for personal ID uisng existing number 3. Make sure no commcare apps are not installed 4. Expand the side navigation drawer and observe that commcare apps option is greyed out | D3: - The option 'CommCare apps' should be greyed out if there are no app installed on the device - The option should be enabled again, if there's atleast one app installled on the device
A4: TC_03 | B4: Verify on signing up with a new PersonalID user we don't see any options in the side drawer menu | C4: 1. Open the app and sign up for PersonalID with a completely new user. 2. On completing the sign up, user should see a new side drawer ootion. 3. Observe that in the side drawer we don't see any options. | D4: - User should not see any connect related options in the side drawer if PersonalID user has not beein invited to any opportunities - User should see 'Refresh Opportunities" option in the 3-dot menu - User should only see greyed out CommCare Apps option in the side drawer. On installing any app, the option should get enabled
A5: TC_04 | B5: Confirm we see the messaging channels only when the channel exists | C5: - For new personal ID: 1. Login with personal ID 2. Create a channel in commcare hq for new personal ID 3. Expand the side navigation drawer 4. Verify messaging option is visible - For exisiting personal ID user whose channel is already created 1. Login with exisiting PID 2. Verify the messaging option is visible | D5: - Messaging option for a new PID user should only be visible after the channel creation - For old existing users, messaging option should be displayed after sign in
A6: TC_05 | B6: Verify that the new user sees "Go to Connect" button on clicking the 'Refresh Opportunity" option | C6: 1. Register with new Personal ID 2. Go to side navigation drawer, verify opportunities option isn't visible 3. Click on the 3 dots menu >> select Refresh opportunities button 4. If any opportunities are invited, new found found message is displayed 5. 'Go to connect' button & opportunities button are displayed | D6: - New PID users should only see the Go to connect menu when they click on refresh opportunities after being invited - If user is not invited to an opportuntiy, clickin refresh button should not display connect options - Refresh button should disappear once the connect option appears
A7: TC_06 | B7: Verify user sees all the installed apps under CommCare Apps section | C7: 1. Login with PID 2. Install few learn/deliver apps 3. Go to side navigation drawer 4. All the installed apps are installed under commcare apps section | D7: - User should see all the apps installed on the device under CommCare Apps - Clicking on the apps should take user to the login page for the selected apps
A8: TC_07 | B8: Confirm user sees there name and picture on the side nav menu | C8: 1. Login with PID 2. Verify PID user name and picture are displayed on side navigation menu | D8: - User should see their name and picture at the top of the left hand menu
A9: TC_08 | B9: Verify on clicking the opportunities option from the side drawer takes you to the opportunity list page | C9: 1. Login with PID user 2. Click on the opportunities option from side navigation drawer 3. Verify user is landed on the opportunities list page | D9: - User should land on the opportunities list page by clicking on the opportunities option
A10: TC_09 | B10: Confirm on receiving a message, we see a red dot on the messaging option | C10: 1. Login with PID user whose channel have been already created 2. Trigger connect messages from commcare hq 3. Observe that on receiving a triggered message, red dot have been highlighted on messaging option in mobile
A11: TC_10 | B11: Verify on clicking the messaging option, user is taken channels list page | C11: 1. Login with PID 2. Click on side navigation menu 3. Select messaging option | D11: - User should land on the channels list page
A12: TC_11 | B12: Confirm that the hamburger menu is visible on the screen even after user has signed out of PersonalID | C12: 1. Click on the hamburger option 2. Click on sign up/register for personal ID option from side nav drawer 3. Login with PID 4. Click on 3 dots menu >> select forget personal ID | D12: The hamburger icon and side nav menu should be visible to the user if they forget the PersonalID
A13: TC_12 | B13: When a new PersonalID user sign up, they should not see the connect options | C13: 1. Click on the hamburger option 2. Click on sign up/register for personal ID option from side nav drawer 3. Register for personal ID using new mobile number 4. Go to side navigation menu 5. Verify no connect options are displayed on the side navigation menu | D13: Connect options aren't displayed on the side navigation menu when sign up with new user
A14: TC_13 | B14: Verify user sees the connect options on clicking "Referesh Opportuntiy" button | C14: "1. Register with new Personal ID 2. Go to side navigation drawer, verify opportunities option isn't visible 3. Invite an user for an opportunity from CCC web UI 4. Click on the 3 dots menu >> select Refresh opportunities button 5. If any opportunities are invited, new found found message is displayed 6. 'Go to connect' button & opportunities button are displayed" | D14: - On inviting a user after sign up,user should sees the connect options on clicking the refresh opportunity option
A15: TC_14 | B15: Verify if user is not invited to an opportunity, on clicking the Refresh opportuntiy button, user isn't able to see any connect option | C15: "1. Register with new Personal ID 2. Go to side navigation drawer, verify opportunities option isn't visible 3. Click on the 3 dots menu >> select Refresh opportunities button 4. "No opprtunities found" message is displayed | D15: - Connect options are not visible upon clicking on 'refresh opportunities' button when no opportunity is invited
A16: TC_15 | B16: Verify user sees the connect options visible to them on receiving the push notification for the invite | C16: 1. Register with new Personal ID 2. Go to side navigation drawer, verify opportunities option isn't visible 3. Invite an user for an opportunity from CCC web UI 4. Push notification is received upon inviting for any opportunity 5. Connect options are also visible | D16: - User should see the connect option on receiving the push notification or when user clicks on it - The "Refresh Opportunity" button should get hidden once the connect functions are visible
A17: TC_16 | B17: Confirm for a pre-invited user, connect options are visible on sign up | C17: 1. Invite an user [who is not registered for personal ID yet] for an opportunity 2. Register with personal ID using the number used in step 1 3. Go to side navigation drawer 4. Verify connect options are visible | D17: - Connect options should be visible for a pre-invited user - User should see the opportunity in the list for which they were invited
A18: TC_17 | B18: Verify mobile users sess all the opportunities that they are invited to on the opportunity list page | C18: 1. Login with PID 2. Go to side navigation menu 3. Select opprtunities option 4. User should be landing on opportunities list page 5. All the opportunities invited for an PID user are listed on the opportunity list page | D18: - Each Opportunity should show the correct values for all fields in the CCC web UI - Each Opportunity should show the correct values for all the opportunities user is part of | G18: 1
A19: TC_18 | B19: Confirm user receivies a text invite message when they are added to the opportunity | C19: Cont from above TC - Verify personal ID mobile number, text message will be received for an opp invite | D19: - User should receive a text message on the number they have the ConnectID account with. - User should be able to click the link and redirected share their info with the project. - The new opportunity should be visible in the opportunity list and "New Opportunity" label should be visible to the user | G19: 1
A20: TC_19 | B20: Verify the user status is updated once the user has accepted to share the information with the project by clicking the link in the text message | C20: Cont from above TC - Click on the link in opp invite text message | D20: - The count for wrokers "Yet to accept invitation" should get updated on the opportunity dashboard - The Work Progress Funnel should get updates as well on opportunity dashboard | G20: 1
A21: TC_20 | B21: Verify on selecting the view opportunity button, user sees the description and all the opportunity details | C21: 1. Sign up for personal ID 2. Click on Go to connect menu 3. Click on the view opportunity | D21: User should see the following details on selecting an opportunity from the list - Description - Learn modules - Delivery details On clicking the "Start" option, learn app should start downloading | G21: 1
A22: TC_21 | B22: Ensure that after downloading the learn app, the opportunity status gets updated on the mobile | C22: Cont from above TC - Click on download learn app | D22: The status for the opportunity should get updated to "InProgress" from "New Opportunity" | G22: 1
A23: TC_22 | B23: Verify user is able to dowload the Learn App from the opportunity | D23: - The Learn App should be downloaded without any issues on the app - User should see the progress on the screen - User should not be able to go back from the downlaod page until the download is complete. (The back button should be disbaled) | G23: 1
A24: TC_23 | B24: Ensure that user is taken to the app home screen after successful download of the Learn App | C24: 1. Sign up for personal ID 2. Click on Go to connect menu 3. Select any opportunity and download learn app | D24: - On successful download of the Learn App, FLW should be autologged into the Learn App - User should be redirected to the app home screen and can start the learning | G24: 1
A25: TC_24 | B25: Verify on submitting the forms, learn app progress is updated in the app | C25: cont from above TC - Submit learn app forms - Click on the view status button - Learn app progress is updated | D25: - User should see the completed progress in % on the learn progress screen - User should see the no. of lessons completed out of total lessons - "Finish learning to earn certificate" message should get displayed - Completed learn progress should get updated on the web UI | G25: 1
A26: TC_25 | B26: Confirm on completing all the learn modules, user sees a Training Pending messgae on the Learn Progress screen | C26: cont from above TC - Submit all the learn app forms[except assessment] - Click on the view status button | D26: - User should see a Training Pending message on completing all the learn modules in Learn Progress screen | G26: 1
A27: TC_26 | B27: Confirm user is unable to claim the job, if they don't pass the assessment | C27: 1. Sign up for personal ID 2. Click on go to connect menu 3. Select and opportunity 4. Submit all learn forms 5. Submit the assessment that doesn't satisfy the pass score | D27: - User should not be able to claim the job if they don't score the min passing score - They should see "Training Failed: Sorry, you did not earn a passing score on your assessment. Please try again." and also see there score and the passing score on the Learn Progress screen - User should also see the failed assessment status in the Learn tab on the worker screen | G27: 1
A28: TC_27 | B28: Verify user can claim the job when they have successfully passed the assessment | C28: 1. Sign up for personal ID 2. Click on go to connect menu 3. Select and opportunity 4. Submit all learn forms 5. Submit the assessment that satisfy the pass score | D28: - User should see a certification when they successfully complete the assessment on the Learn Progress screen - User should also see a message "You have passed the assessment and are ready to deliver. View job status to proceed" message on the app home screen - The status under Learn tab for assessments should also get updated to Passed now.. | G28: 1
A29: TC_28 | B29: Confirm that user sees the Delivery details on the screen when they click on the "View Opportunity Details" button | C29: cont from above TC - Claim job by clicking on the view opportunity details button | D29: i) User should see all the delivery details on the screen with - Total Max visits - Max visits per day - Total no of days left - Max amount user can earn with the visits ii) User should also be able to download the delivery app | G29: 1
A30: TC_29 | B30: Verify the number of visits is updated in the app after successfully conducting a visit | C30: cont from above TC - Submit few visits | D30: - Should be updated on the app - The visit should be reflected in the Connect Web - There should be a new pending entry in the 'Verification & Payments' tab | G30: 1
A31: TC_30 | B31: Verify on approving a visit on connect web, the status is updated in the app as well | C31: 1. On web UI, for the pending visits approve the visits from visit verification page from an opportunity 2. Sign up for personal ID in mobile 3. Click on "Go to connect menu" 4. select the opportunity used in step 1 5. Click on view status button 6. Select payment unit, you will land on the visit status tab 7. Visit status should get updated | D31: - The visit status should get update under Deliver tab on the worker page - The status should also get updated in the mobile on the delivery progress screen, under Progress tab - User should see all the payment units for the opportunity on the delivery progress screen | G31: 1
A32: TC_31 | B32: Verify that user can see a payment record under payment tab | C32: 1. Sign up for personal ID 2. Navigate to opportunity list page 3. Select an opportunity with deliver status 4. Click on view status button 5. Select payment tab | D32: User should see a payment status, under Payment tab on the Delivery Progress screen - Earned Amount - Transferred Amount | G32: 1
A33: TC_32 | B33: Verify user can only do the max visits allowed to them on a single day | C33: 1. Sign up for personal ID 2. Navigate to opportunity list page 3. Select an opportunity with deliver status 4. Submit the visits that satisfies the daily limit | D33: - On exceeding the delviery forms limit, user should not see any progress getting updated on the mobile app. - User should not see the count of Verification Status getting updated in Verification & Payments tab - On Web UI, user should see a 'Over Limit' status for the form submitted on after exceeding the daily limit, under Deliver Forms tab | G33: 1
A34: TC_33 | B34: Confirm user can continue the delivery progress on a new device by recovering their account | C34: 1. Sign up for personal ID on another device | D34: User should be able to recover the account successfully and no progress should be lost | G34: 1
A35: TC_34 | B35: Check if user uninstalls the Learn/Deliver App, would they be able to re-install the Learn/Deliver Apps by clicking on resume button | C35: 1. Click on three dots menu in mobile 2. select app manager 3. Uninstall all the learn/deliver apps 4. Go to opp list page 5. Click on resume button | D35: The Learn/Delvier apps should be downloaded again on clicking the resume button on opp card
A36: TC_35 | B36: Verify the submission of same form doesn't increase the daily visit progress | C36: 1. Submit visit 1 2. Submit visit 2 with same details of visit 1 | D36: The progress screen should not increment the submitted numbers - On web the 2nd visit should mark as duplicate
A37: TC_36 | B37: Clicking on Opportunity invite Push Notification should take user to the Opportunity details page | D37: User should be redirected to the opportunity details page
A38: TC_37 | B38: Verify on completion of the download oflearn app user should be automatically taken to the app, to start learning | D38: User is logged in automatically on successful download of the learn app and should be able to start the learning | G38: 1
A39: TC_38 | B39: If I have not come back and taken a lesson for the past 3 days, I should receive a push notification nudging me to complete the learning. The push notification should link me directly into the Learn app for that Opportunity
A40: TC_39 | B40: If the last date has already been reached, the button on the Review Delivery Details screen should be grayed out and the text above it should read: “The last date for the project is over. You will be notified if the opportunity opens up again’
...

Sheet Connect Landing Page
B1: Description | C1: Steps | D1: Expected Outcome | E1: Status (Pass/Fail) | F1: Ticket/ Bug ID | G1: Comments
A2: OLP_01 | B2: Verify “In Progress” Opportunities Displayed at Top | C2: 1. Install latest test apk 2. Sign up for personal ID 3. Go to connect menu | D2: - "InProgress" section is displayed at the top of opportunities list page
A3: OLP_02 | B3: Verify “New” Opportunities Displayed Below In Progress | C3: 1. Install latest test apk 2. Sign up for personal ID 3. Go to connect menu | D3: - "New Opportunities" section is displayed below the inprogress section
A4: OLP_03 | B4: Verify "Completed opportunities" section displayed at bottom | C4: 1. Install latest test apk 2. Sign up for personal ID 3. Go to connect menu | D4: - "Completed Opportunities" section is displayed at the bottom of opportunities list page
A5: OLP_04 | B5: Verify User Can View Opportunity Information at Any Time | C5: 1. Install latest test apk 2. Sign up for personal ID 3. Go to connect menu 4.Click on the view info option for an inprogress opp 5. Repeat step 4 for completed opp | D5: - We show see the Opp information details at any time when user click on view info option
A6: OLP_05 | B6: Verify Opportunity Details Drawer Opens | C6: cont to above TC - When we click on the view info button Opportunity details drawer opens | D6: - When user clicks on "view info" option Opp details drawer is opened
A7: OLP_06 | B7: Verify Drawer Displays Complete Opportunity Information | C7: 1. Install latest test apk 2. Sign up for personal ID 3. Go to connect menu >> Click on view info option for an Opp | D7: The following details are shown: - Complete by date - Work history progress using icons - Delivery Details
A8: OLP_07 | B8: Verify Correct Progress Display for Opportunity | C8: 1. Install latest test apk 2. Sign up for personal ID 3. Go to connect menu 4. Verify learn progress or delivery progress are shown | D8: - Learn progress badge is displayed correctly for opportunities which have learn app is in progress - Delivery progress badge is displayed correctly for opp which have delivery app is in progress - Percentage shown matches actual backend progress. - Progress updates accurately based on user activity.
A9: OLP_08 | B9: Verify Work History progress is shown on opportunity details | C9: 1. Install latest test apk 2. Sign up for personal ID 3. Go to connect menu 4. Click on the "View info" option for an opp 5. Verify worker history progress is shown on the opp details drawer | D9: - Work history progress is visible in the opportunity details drawer. - Icons/status indicators reflect correct progress state
A10: OLP_09 | B10: Verify user is able to see review and view info options to the completed opportunities | C10: 1. Install latest test apk 2. Sign up for personal ID 3. Go to connect menu | D10: Completed opportunities display both Review and View Info options.
A11: OLP_10 | B11: Verify user is able to see the resume and view info options to the InProgress Opportunities | C11: 1. Install latest test apk 2. Sign up for personal ID 3. Go to connect menu | D11: In Progress opportunities display Resume and View Info options.
A12: OLP_11 | B12: Verify user is able to see the view opportunity button for New Opportunities | C12: 1. Install latest test apk 2. Sign up for personal ID 3. Go to connect menu 4. Invite a new opp from web | D12: New opportunities display the View opportunity button.
A13: OLP_12 | B13: Verify user is able to start the opportunity upon clicking on view opportunity button | C13: 1. Install latest test apk 2. Sign up for personal ID 3. Go to connect menu 4. Invite a new Opp from web 5. Click on the view opportunity button 6. On opp details page click on start button | D13: - User lands on the opportunity details page - User sees the start button - Learn app starts downloading upon clicking on the start button
... A24: OLP_23 | B24: Verify user is able to see the delivery progress badge with 0% when delivery app is not started | C24: 1. Sign up for PID 2. Invite for an Opp 3. Complete learn apps and download the delivery app (don't start any progress) | D24: - User should see the progress as 0% along with delivery progress badge
A25: OLP_24 | B25: Verify completion date is shown in red colour if user have not completed the opportunity before 5 days of expire | D25: Completion date appears in red color with info icon when opportunity is within 5 days of expiry and incomplete
A26: OLP_25 | B26: Verify user shouldn't see any date or red color date text for completed opportunities | D26: No red color date should be displayed for opps under completed section
A27: OLP_26 | B27: Verify no progress badge is displayed for opps under completed section | D27: No Progress icon should be there for opps under completed section
A28: OLP_27 | B28: Verfiy green check mark is displayed for opps which completed all visits | C28: 1. Install latest test apk 2. Sign up for personal ID 3. Go to connect menu 4. Complete all the visits for an Opp | D28: Green check mark should get updated upon completing all visits
A29: OLP_28 | B29: Verify user is able to download learn/delivery app using review option [completed opp] | C29: 1. Install latest test apk 2. Sign up for personal ID 3. Go to connect menu 4. Click on the review button | D29: - Clicking Review redirects user to Learn/Delivery progress page of app if installed. - If not installed, user is redirected to the download page.

Sheet Connect messaging
A1: Prerequsite: A PID user should get created and login to the learn app, submit few forms.
A2: Test Case ID | B2: Description | C2: Steps | D2: Outcome | E2: Status (Pass/Fail) | F2: QA Ticket | G2: Comments
A3: Connect channel 1 | B3: Verify user is able to create connect channel | C3: 1. Login to CC hq 2. Navigate to messaging >> view all 3. Under connect messaging section, Select user conset 4. Click Request messaging consent button | D3: - Channel created for a personal ID message is displayed on hq web - Channel should get created and displayed in the connect mobile
A4: Connect message1 | B4: Verify user is able to create a broadcast with connect message option | C4: 1. Login to CC hq 2. Navigate to Messaging >> Broadcasts 3. Click on "+ Add broadcast" 4. Select the content type as 'connect message' 5. Create a broadcast 6. Verify PID user recive a message on the channel | D4: - User should be able to receive the broadcast message in the connect channel
A5: Connect message2 | B5: Verify user is able to create a broadcast with connect survey option | C5: 1. Login to CC hq 2. Navigate to Messaging >> Broadcasts 3. Click on "+ Add broadcast" 4. Select the content type as 'connect Survey' 5. Create a broadcast 6 Verify PID user recive a message on the channel | D5: - User should be able to receive the broadcast survey in the connect channel - User should be able to answer the question and get next question in the form - Form should get submit and able to verify it on the submit histstory
A6: Connect message3 | B6: Verify user is able to create a Conditional alerts with connect message option | C6: 1. Login to CC hq 2. Navigate to Messaging >> Conditional alert 3. Click on "+ Conditional alert" 4. Select the content type as 'connect message' 5. Create a Conditional alert 6. Submit a form with PID user used to create CA by satisfying the alert condition 7 Verify PID user recive a message on the channel | D6: - User should be able to get a alert message in the connect channel upon submitting the form satisfying the alert condition
A7: Connect message4 | B7: Verify user is able to create a conditional alerts with connect survey option | C7: 1. Login to CC hq 2. Navigate to Messaging >> Conditional alert 3. Click on "+ Conditional alert" 4. Select the content type as 'connect survey' 5. Create a Conditional alert 6. Submit a form with PID user used to create CA by satisfying the alert condition 7 Verify PID user recive a message on the channel | D7: - User should be able to get a alert survey message in the connect channel upon submitting the form satisfying the alert condition - User should be able to answer the question and get next question in the form - Form should get submit and able to verify it on the submit histstory
A8: Connect message5 | B8: Verify user is able to create keyword for connect message | C8: 1. Login to CC hq web UI 2. Navigate to Messaging >> keyword 3. Select 'connect message' as content type 4. Create a keyword 5. Login with personal ID [CCC mobile] 5. Trigger keyword from channel 6. verify user receive a connect message in the channel to the personal ID user | D8: - User should get a connect message in the channel upon triggering the keyword
